<?xml version="1.0" ?>
<!-- =================================================================================== -->
<!-- |    This document was autogenerated by xacro from /home/alaurenzi/code/robots_ws/src/iit-centauro-ros-pkg/centauro_urdf/urdf/centauro.urdf.xacro | -->
<!-- |    EDITING THIS FILE BY HAND IS NOT RECOMMENDED                                 | -->
<!-- =================================================================================== -->
<robot name="centauro">
  <!-- 
  ROS urdf definition of the CENTAURO humanoid robot by Istituto Italiano di Tecnologia
  
  Author: Enrico Mingo Hoffman
-->
  <!-- scaling facto for available peack torque link side, from 0 to 1 -->
  <material name="black">
    <color rgba="0.4 0.4 0.4 1"/>
  </material>
  <material name="dark">
    <color rgba="0.1 0.1 0.1 1"/>
  </material>
  <material name="dark_grey">
    <color rgba="0.2 0.2 0.2 1"/>
  </material>
  <!-- Note: the "23" suffix denotes the new bigger-size wheel -->
  <!-- ??? -->
  <!-- ??? -->
  <!-- Origin -->
  <!-- <xacro:property name="hip_yaw_lower" value="${[-2.827,-2.583, -2.583 ,-2.827]}"/>
<xacro:property name="hip_yaw_upper" value="${[ 2.583, 2.827,  2.827 , 2.583]}"/> -->
  <link name="base_link"/>
  <link name="pelvis">
    <inertial>
      <origin xyz="-0.0016320207 0.0026534004000000003 0.079167428"/>
      <mass value="26.584529"/>
      <inertia ixx="0.39195477" ixy="0.024781258999999996" ixz="0.017108606999999998" iyy="1.0000708999999999" iyz="0.0052627106000000005" izz="1.0679988999999999"/>
    </inertial>
    <visual>
      <origin rpy="0.0 0.0 0.0" xyz="0.0 0 0.0"/>
      <geometry>
        <mesh filename="package://centauro_urdf/meshes/v2/pelvis.stl" scale="0.001 0.001 0.001"/>
      </geometry>
    </visual>
    <collision>
      <origin rpy="0.0 0.0 0.0" xyz="0.0 0 0.0"/>
      <geometry>
        <mesh filename="package://centauro_urdf/meshes/simple/pelvis.stl" scale="0.001 0.001 0.001"/>
      </geometry>
    </collision>
  </link>
  <link name="imu_link"/>
  <joint name="imu_joint" type="fixed">
    <parent link="pelvis"/>
    <origin rpy="0.0 0.0 0.0" xyz="0.248316 0.0 0.015"/>
    <child link="imu_link"/>
  </joint>
  <joint name="base_joint" type="fixed">
    <parent link="pelvis"/>
    <child link="base_link"/>
    <origin rpy="0 0 0" xyz="0 0 0"/>
  </joint>
  <!-- /macro centauro_wheel -->
  <!-- /macro arms -->
  <!-- /macro legs -->
  <link name="hip1_1">
    <inertial>
      <origin xyz="0.0003595855 0.033338818000000006 -0.059190309"/>
      <mass value="2.3349153"/>
      <!-- org: 2 -->
      <inertia ixx="0.0068405374" ixy="1.8572633e-05" ixz="-4.8325972e-05" iyy="0.0026261815" iyz="0.0001564273" izz="0.0066933354"/>
    </inertial>
    <visual>
      <origin rpy="0.0 0.0 0.0" xyz="0.0 0.0 0.0"/>
      <geometry>
        <mesh filename="package://centauro_urdf/meshes/v2/hip-yaw.stl" scale="0.001 -0.001 0.001"/>
      </geometry>
      <material name="dark_grey"/>
    </visual>
    <collision>
      <origin rpy="0.0 0.0 0.0" xyz="0.0 0.0 0.0"/>
      <geometry>
        <mesh filename="package://centauro_urdf/meshes/v2/collision/hip-yaw.stl" scale="0.001 -0.001 0.001"/>
      </geometry>
    </collision>
  </link>
  <link name="hip2_1">
    <inertial>
      <origin xyz="-4.6285952e-06 -0.2214019 0.03316685"/>
      <mass value="3.4572118"/>
      <!-- org: 4.5 -->
      <inertia ixx="0.050469853" ixy="-7.784938699999999e-06" ixz="-9.220580999999999e-06" iyy="0.008181596999999999" iyz="0.0059796848" izz="0.048213808999999996"/>
    </inertial>
    <visual>
      <origin rpy="0.0 0.0 0.0" xyz="0.0 0.0 0.0"/>
      <geometry>
        <mesh filename="package://centauro_urdf/meshes/v2/hip-pitch.stl" scale="0.001 0.001 -0.001"/>
      </geometry>
    </visual>
    <collision>
      <origin rpy="0.0 0.0 0.0" xyz="0.0 0.0 0.0"/>
      <geometry>
        <mesh filename="package://centauro_urdf/meshes/v2/collision/hip-pitch.stl" scale="0.001 0.001 -0.001"/>
      </geometry>
    </collision>
  </link>
  <link name="knee_1">
    <inertial>
      <origin xyz="0.00012063381 0.14620674 0.029740711000000003"/>
      <mass value="2.1199315"/>
      <!-- org: 3.5, foot un modeled-->
      <inertia ixx="0.018426402999999997" ixy="2.8226635999999997e-05" ixz="-2.9204348e-05" iyy="0.0047685615" iyz="-0.002640771" izz="0.017793722"/>
    </inertial>
    <visual>
      <origin rpy="0.0 0.0 0.0" xyz="0.0 0.0 0.0"/>
      <geometry>
        <mesh filename="package://centauro_urdf/meshes/v2/knee.stl" scale="0.001 0.001 -0.001"/>
      </geometry>
      <material name="dark_grey"/>
    </visual>
    <collision>
      <origin rpy="0.0 0.0 0.0" xyz="0.0 0.0 0.0"/>
      <geometry>
        <mesh filename="package://centauro_urdf/meshes/v2/collision/knee.stl" scale="0.001 0.001 -0.001"/>
      </geometry>
    </collision>
  </link>
  <link name="ankle1_1">
    <inertial>
      <origin xyz="0.00012360094 -0.06274712 -0.0049068453"/>
      <mass value="1.4023368"/>
      <!-- org: 3.5, foot un modeled-->
      <inertia ixx="0.0049928829" ixy="5.762355699999999e-06" ixz="1.9606394e-05" iyy="0.0017621464" iyz="0.00045315091" izz="0.0048706328"/>
    </inertial>
    <visual>
      <origin rpy="0.0 0.0 0.0" xyz="0.0 0.0 0.0"/>
      <geometry>
        <mesh filename="package://centauro_urdf/meshes/v2/ankle-pitch.stl" scale="0.001 0.001 -0.001"/>
      </geometry>
    </visual>
    <collision>
      <origin rpy="0.0 0.0 0.0" xyz="0.0 0.0 0.0"/>
      <geometry>
        <mesh filename="package://centauro_urdf/meshes/v2/collision/ankle-pitch.stl" scale="0.001 0.001 -0.001"/>
      </geometry>
    </collision>
  </link>
  <link name="ankle2_1">
    <inertial>
      <origin xyz="0.00018512273 0.0017369405000000001 -0.091340683"/>
      <mass value="2.440929"/>
      <!-- org: 3.5, foot un modeled-->
      <inertia ixx="0.017711499" ixy="1.0713141e-05" ixz="-2.2094697e-05" iyy="0.014263485" iyz="0.00033426702" izz="0.0080747557"/>
    </inertial>
    <visual>
      <origin rpy="0.0 0.0 0.0" xyz="0.0 0.0 0.0"/>
      <geometry>
        <mesh filename="package://centauro_urdf/meshes/v2/mesh_ankle-yaw_wheel23.stl" scale="0.001 -0.001 0.001"/>
      </geometry>
      <material name="dark_grey"/>
    </visual>
    <collision>
      <origin rpy="0.0 0.0 0.0" xyz="0.0 0.0 0.0"/>
      <geometry>
        <mesh filename="package://centauro_urdf/meshes/v2/collision/mesh_ankle-yaw_wheel23.stl" scale="0.001 -0.001 0.001"/>
      </geometry>
    </collision>
  </link>
  <joint name="j_wheel_1" type="continuous">
    <parent link="ankle2_1"/>
    <child link="wheel_1"/>
    <origin rpy="1.57079632679 0.0 0.0" xyz="0.0 -0.0 -0.14435"/>
    <axis xyz="0 0 -1"/>
    <limit effort="35" velocity="20.0"/>
    <!-- 23 Nm, 1
            rad/s-->
  </joint>
  <link name="wheel_1">
    <inertial>
      <origin xyz="0.0 0.0 0.00015403767"/>
      <mass value="1.8569388"/>
      <inertia ixx="0.008637359099999999" ixy="0.0" ixz="-0.0" iyy="0.0086373644" iyz="-0.0" izz="0.016376551"/>
    </inertial>
    <visual>
      <origin rpy="0.0 0.0 0.0" xyz="0.0 0.0 0.0"/>
      <geometry>
        <mesh filename="package://centauro_urdf/meshes/v2/mesh_wheel23.stl" scale="0.001 0.001 -0.001"/>
      </geometry>
      <material name="black"/>
    </visual>
    <collision>
      <origin rpy="0 0 0" xyz="0 0 0"/>
      <geometry>
        <mesh filename="package://centauro_urdf/meshes/v2/collision/mesh_wheel23.stl" scale="0.001 0.001 -0.001"/>
      </geometry>
      <material name="black"/>
    </collision>
  </link>
  <!-- *****************************-->
  <link name="contact_1"/>
  <joint name="contact_joint_1" type="fixed">
    <parent link="ankle2_1"/>
    <child link="contact_1"/>
    <origin rpy="0 0 0" xyz="0 0 -0.176"/>
  </joint>
  <!-- ******************************** -->
  <joint name="hip_yaw_1" type="revolute">
    <parent link="pelvis"/>
    <child link="hip1_1"/>
    <origin rpy="0.0 0.0 0.0" xyz="0.25 0.125 -0.056600000000000004"/>
    <axis xyz="0 0 -1"/>
    <limit effort="304" lower="-2.03" upper="2.51" velocity="8.8"/>
    <!-- 200 Nm, 1 rad/s-->
  </joint>
  <joint name="hip_pitch_1" type="revolute">
    <parent link="hip1_1"/>
    <child link="hip2_1"/>
    <origin rpy="1.57079632679 0.0 0.0" xyz="0.0 0.1146 -0.0625"/>
    <axis xyz="0 0 -1"/>
    <limit effort="304" lower="-2.0226" upper="2.02748" velocity="8.8"/>
    <!-- 200 Nm, 1 rad/s-->
  </joint>
  <joint name="knee_pitch_1" type="revolute">
    <parent link="hip2_1"/>
    <child link="knee_1"/>
    <origin rpy="3.14159265359 0.0 0.0" xyz="0.0 -0.3 0.1182"/>
    <axis xyz="0 0 -1"/>
    <limit effort="304" lower="-2.4056" upper="2.3994" velocity="8.8"/>
    <!-- 200 Nm, 1 rad/s-->
  </joint>
  <joint name="ankle_pitch_1" type="revolute">
    <parent link="knee_1"/>
    <child link="ankle1_1"/>
    <origin rpy="3.14159265359 0.0 0.0" xyz="0.0 0.2 0.10015"/>
    <axis xyz="0 0 -1"/>
    <limit effort="147" lower="-2.4056" upper="2.3184" velocity="8.1"/>
    <!-- 98 Nm, 1 rad/s-->
  </joint>
  <joint name="ankle_yaw_1" type="revolute">
    <parent link="ankle1_1"/>
    <child link="ankle2_1"/>
    <origin rpy="-1.57079632679 0.0 0.0" xyz="0.0 -0.139 -0.00085"/>
    <axis xyz="0 0 -1"/>
    <limit effort="35" lower="-2.5626" upper="2.5384" velocity="20.0"/>
    <!-- 23 Nm, 1 rad/s-->
  </joint>
  <link name="hip1_2">
    <inertial>
      <origin xyz="0.0003595855 -0.033338818000000006 -0.059190309"/>
      <mass value="2.3349153"/>
      <!-- org: 2 -->
      <inertia ixx="0.0068405374" ixy="-1.8572633e-05" ixz="-4.8325972e-05" iyy="0.0026261815" iyz="-0.0001564273" izz="0.0066933354"/>
    </inertial>
    <visual>
      <origin rpy="0.0 0.0 0.0" xyz="0.0 0.0 0.0"/>
      <geometry>
        <mesh filename="package://centauro_urdf/meshes/v2/hip-yaw.stl" scale="0.001 0.001 0.001"/>
      </geometry>
      <material name="dark_grey"/>
    </visual>
    <collision>
      <origin rpy="0.0 0.0 0.0" xyz="0.0 0.0 0.0"/>
      <geometry>
        <mesh filename="package://centauro_urdf/meshes/v2/collision/hip-yaw.stl" scale="0.001 0.001 0.001"/>
      </geometry>
    </collision>
  </link>
  <link name="hip2_2">
    <inertial>
      <origin xyz="-4.6285952e-06 -0.2214019 -0.03316685"/>
      <mass value="3.4572118"/>
      <!-- org: 4.5 -->
      <inertia ixx="0.050469853" ixy="-7.784938699999999e-06" ixz="9.220580999999999e-06" iyy="0.008181596999999999" iyz="-0.0059796848" izz="0.048213808999999996"/>
    </inertial>
    <visual>
      <origin rpy="0.0 0.0 0.0" xyz="0.0 0.0 0.0"/>
      <geometry>
        <mesh filename="package://centauro_urdf/meshes/v2/hip-pitch.stl" scale="0.001 0.001 0.001"/>
      </geometry>
    </visual>
    <collision>
      <origin rpy="0.0 0.0 0.0" xyz="0.0 0.0 0.0"/>
      <geometry>
        <mesh filename="package://centauro_urdf/meshes/v2/collision/hip-pitch.stl" scale="0.001 0.001 0.001"/>
      </geometry>
    </collision>
  </link>
  <link name="knee_2">
    <inertial>
      <origin xyz="0.00012063381 0.14620674 -0.029740711000000003"/>
      <mass value="2.1199315"/>
      <!-- org: 3.5, foot un modeled-->
      <inertia ixx="0.018426402999999997" ixy="2.8226635999999997e-05" ixz="2.9204348e-05" iyy="0.0047685615" iyz="0.002640771" izz="0.017793722"/>
    </inertial>
    <visual>
      <origin rpy="0.0 0.0 0.0" xyz="0.0 0.0 0.0"/>
      <geometry>
        <mesh filename="package://centauro_urdf/meshes/v2/knee.stl" scale="0.001 0.001 0.001"/>
      </geometry>
      <material name="dark_grey"/>
    </visual>
    <collision>
      <origin rpy="0.0 0.0 0.0" xyz="0.0 0.0 0.0"/>
      <geometry>
        <mesh filename="package://centauro_urdf/meshes/v2/collision/knee.stl" scale="0.001 0.001 0.001"/>
      </geometry>
    </collision>
  </link>
  <link name="ankle1_2">
    <inertial>
      <origin xyz="0.00012360094 -0.06274712 0.0049068453"/>
      <mass value="1.4023368"/>
      <!-- org: 3.5, foot un modeled-->
      <inertia ixx="0.0049928829" ixy="5.762355699999999e-06" ixz="-1.9606394e-05" iyy="0.0017621464" iyz="-0.00045315091" izz="0.0048706328"/>
    </inertial>
    <visual>
      <origin rpy="0.0 0.0 0.0" xyz="0.0 0.0 0.0"/>
      <geometry>
        <mesh filename="package://centauro_urdf/meshes/v2/ankle-pitch.stl" scale="0.001 0.001 0.001"/>
      </geometry>
    </visual>
    <collision>
      <origin rpy="0.0 0.0 0.0" xyz="0.0 0.0 0.0"/>
      <geometry>
        <mesh filename="package://centauro_urdf/meshes/v2/collision/ankle-pitch.stl" scale="0.001 0.001 0.001"/>
      </geometry>
    </collision>
  </link>
  <link name="ankle2_2">
    <inertial>
      <origin xyz="0.00018512273 -0.0017369405000000001 -0.091340683"/>
      <mass value="2.440929"/>
      <!-- org: 3.5, foot un modeled-->
      <inertia ixx="0.017711499" ixy="-1.0713141e-05" ixz="-2.2094697e-05" iyy="0.014263485" iyz="-0.00033426702" izz="0.0080747557"/>
    </inertial>
    <visual>
      <origin rpy="0.0 0.0 0.0" xyz="0.0 0.0 0.0"/>
      <geometry>
        <mesh filename="package://centauro_urdf/meshes/v2/mesh_ankle-yaw_wheel23.stl" scale="0.001 0.001 0.001"/>
      </geometry>
      <material name="dark_grey"/>
    </visual>
    <collision>
      <origin rpy="0.0 0.0 0.0" xyz="0.0 0.0 0.0"/>
      <geometry>
        <mesh filename="package://centauro_urdf/meshes/v2/collision/mesh_ankle-yaw_wheel23.stl" scale="0.001 0.001 0.001"/>
      </geometry>
    </collision>
  </link>
  <joint name="j_wheel_2" type="continuous">
    <parent link="ankle2_2"/>
    <child link="wheel_2"/>
    <origin rpy="1.57079632679 0.0 0.0" xyz="0.0 0.0 -0.14435"/>
    <axis xyz="0 0 1"/>
    <limit effort="35" velocity="20.0"/>
    <!-- 23 Nm, 1
            rad/s-->
  </joint>
  <link name="wheel_2">
    <inertial>
      <origin xyz="0.0 0.0 -0.00015403767"/>
      <mass value="1.8569388"/>
      <inertia ixx="0.008637359099999999" ixy="0.0" ixz="0.0" iyy="0.0086373644" iyz="0.0" izz="0.016376551"/>
    </inertial>
    <visual>
      <origin rpy="0.0 0.0 0.0" xyz="0.0 0.0 0.0"/>
      <geometry>
        <mesh filename="package://centauro_urdf/meshes/v2/mesh_wheel23.stl" scale="0.001 0.001 0.001"/>
      </geometry>
      <material name="black"/>
    </visual>
    <collision>
      <origin rpy="0 0 0" xyz="0 0 0"/>
      <geometry>
        <mesh filename="package://centauro_urdf/meshes/v2/collision/mesh_wheel23.stl" scale="0.001 0.001 0.001"/>
      </geometry>
      <material name="black"/>
    </collision>
  </link>
  <!-- *****************************-->
  <link name="contact_2"/>
  <joint name="contact_joint_2" type="fixed">
    <parent link="ankle2_2"/>
    <child link="contact_2"/>
    <origin rpy="0 0 0" xyz="0 0 -0.176"/>
  </joint>
  <!-- ******************************** -->
  <joint name="hip_yaw_2" type="revolute">
    <parent link="pelvis"/>
    <child link="hip1_2"/>
    <origin rpy="0.0 0.0 0.0" xyz="0.25 -0.125 -0.056600000000000004"/>
    <axis xyz="0 0 -1"/>
    <limit effort="304" lower="-2.51" upper="2.03" velocity="8.8"/>
    <!-- 200 Nm, 1 rad/s-->
  </joint>
  <joint name="hip_pitch_2" type="revolute">
    <parent link="hip1_2"/>
    <child link="hip2_2"/>
    <origin rpy="1.57079632679 0.0 0.0" xyz="0.0 -0.1146 -0.0625"/>
    <axis xyz="0 0 1"/>
    <limit effort="304" lower="-2.0156" upper="2.0354" velocity="8.8"/>
    <!-- 200 Nm, 1 rad/s-->
  </joint>
  <joint name="knee_pitch_2" type="revolute">
    <parent link="hip2_2"/>
    <child link="knee_2"/>
    <origin rpy="3.14159265359 0.0 0.0" xyz="0.0 -0.3 -0.1182"/>
    <axis xyz="0 0 1"/>
    <limit effort="304" lower="-2.4006" upper="2.4034" velocity="8.8"/>
    <!-- 200 Nm, 1 rad/s-->
  </joint>
  <joint name="ankle_pitch_2" type="revolute">
    <parent link="knee_2"/>
    <child link="ankle1_2"/>
    <origin rpy="3.14159265359 0.0 0.0" xyz="0.0 0.2 -0.10015"/>
    <axis xyz="0 0 1"/>
    <limit effort="147" lower="-2.3266" upper="2.3914" velocity="8.1"/>
    <!-- 98 Nm, 1 rad/s-->
  </joint>
  <joint name="ankle_yaw_2" type="revolute">
    <parent link="ankle1_2"/>
    <child link="ankle2_2"/>
    <origin rpy="-1.57079632679 0.0 0.0" xyz="0.0 -0.139 0.00085"/>
    <axis xyz="0 0 -1"/>
    <limit effort="35" lower="-2.5546" upper="2.5484" velocity="20.0"/>
    <!-- 23 Nm, 1 rad/s-->
  </joint>
  <link name="hip1_3">
    <inertial>
      <origin xyz="0.0003595855 0.033338818000000006 -0.059190309"/>
      <mass value="2.3349153"/>
      <!-- org: 2 -->
      <inertia ixx="0.0068405374" ixy="1.8572633e-05" ixz="-4.8325972e-05" iyy="0.0026261815" iyz="0.0001564273" izz="0.0066933354"/>
    </inertial>
    <visual>
      <origin rpy="0.0 0.0 0.0" xyz="0.0 0.0 0.0"/>
      <geometry>
        <mesh filename="package://centauro_urdf/meshes/v2/hip-yaw.stl" scale="0.001 -0.001 0.001"/>
      </geometry>
      <material name="dark_grey"/>
    </visual>
    <collision>
      <origin rpy="0.0 0.0 0.0" xyz="0.0 0.0 0.0"/>
      <geometry>
        <mesh filename="package://centauro_urdf/meshes/v2/collision/hip-yaw.stl" scale="0.001 -0.001 0.001"/>
      </geometry>
    </collision>
  </link>
  <link name="hip2_3">
    <inertial>
      <origin xyz="-4.6285952e-06 -0.2214019 0.03316685"/>
      <mass value="3.4572118"/>
      <!-- org: 4.5 -->
      <inertia ixx="0.050469853" ixy="-7.784938699999999e-06" ixz="-9.220580999999999e-06" iyy="0.008181596999999999" iyz="0.0059796848" izz="0.048213808999999996"/>
    </inertial>
    <visual>
      <origin rpy="0.0 0.0 0.0" xyz="0.0 0.0 0.0"/>
      <geometry>
        <mesh filename="package://centauro_urdf/meshes/v2/hip-pitch.stl" scale="0.001 0.001 -0.001"/>
      </geometry>
    </visual>
    <collision>
      <origin rpy="0.0 0.0 0.0" xyz="0.0 0.0 0.0"/>
      <geometry>
        <mesh filename="package://centauro_urdf/meshes/v2/collision/hip-pitch.stl" scale="0.001 0.001 -0.001"/>
      </geometry>
    </collision>
  </link>
  <link name="knee_3">
    <inertial>
      <origin xyz="0.00012063381 0.14620674 0.029740711000000003"/>
      <mass value="2.1199315"/>
      <!-- org: 3.5, foot un modeled-->
      <inertia ixx="0.018426402999999997" ixy="2.8226635999999997e-05" ixz="-2.9204348e-05" iyy="0.0047685615" iyz="-0.002640771" izz="0.017793722"/>
    </inertial>
    <visual>
      <origin rpy="0.0 0.0 0.0" xyz="0.0 0.0 0.0"/>
      <geometry>
        <mesh filename="package://centauro_urdf/meshes/v2/knee.stl" scale="0.001 0.001 -0.001"/>
      </geometry>
      <material name="dark_grey"/>
    </visual>
    <collision>
      <origin rpy="0.0 0.0 0.0" xyz="0.0 0.0 0.0"/>
      <geometry>
        <mesh filename="package://centauro_urdf/meshes/v2/collision/knee.stl" scale="0.001 0.001 -0.001"/>
      </geometry>
    </collision>
  </link>
  <link name="ankle1_3">
    <inertial>
      <origin xyz="0.00012360094 -0.06274712 -0.0049068453"/>
      <mass value="1.4023368"/>
      <!-- org: 3.5, foot un modeled-->
      <inertia ixx="0.0049928829" ixy="5.762355699999999e-06" ixz="1.9606394e-05" iyy="0.0017621464" iyz="0.00045315091" izz="0.0048706328"/>
    </inertial>
    <visual>
      <origin rpy="0.0 0.0 0.0" xyz="0.0 0.0 0.0"/>
      <geometry>
        <mesh filename="package://centauro_urdf/meshes/v2/ankle-pitch.stl" scale="0.001 0.001 -0.001"/>
      </geometry>
    </visual>
    <collision>
      <origin rpy="0.0 0.0 0.0" xyz="0.0 0.0 0.0"/>
      <geometry>
        <mesh filename="package://centauro_urdf/meshes/v2/collision/ankle-pitch.stl" scale="0.001 0.001 -0.001"/>
      </geometry>
    </collision>
  </link>
  <link name="ankle2_3">
    <inertial>
      <origin xyz="0.00018512273 0.0017369405000000001 -0.091340683"/>
      <mass value="2.440929"/>
      <!-- org: 3.5, foot un modeled-->
      <inertia ixx="0.017711499" ixy="1.0713141e-05" ixz="-2.2094697e-05" iyy="0.014263485" iyz="0.00033426702" izz="0.0080747557"/>
    </inertial>
    <visual>
      <origin rpy="0.0 0.0 0.0" xyz="0.0 0.0 0.0"/>
      <geometry>
        <mesh filename="package://centauro_urdf/meshes/v2/mesh_ankle-yaw_wheel23.stl" scale="0.001 -0.001 0.001"/>
      </geometry>
      <material name="dark_grey"/>
    </visual>
    <collision>
      <origin rpy="0.0 0.0 0.0" xyz="0.0 0.0 0.0"/>
      <geometry>
        <mesh filename="package://centauro_urdf/meshes/v2/collision/mesh_ankle-yaw_wheel23.stl" scale="0.001 -0.001 0.001"/>
      </geometry>
    </collision>
  </link>
  <joint name="j_wheel_3" type="continuous">
    <parent link="ankle2_3"/>
    <child link="wheel_3"/>
    <origin rpy="1.57079632679 0.0 0.0" xyz="0.0 -0.0 -0.14435"/>
    <axis xyz="0 0 -1"/>
    <limit effort="35" velocity="20.0"/>
    <!-- 23 Nm, 1
            rad/s-->
  </joint>
  <link name="wheel_3">
    <inertial>
      <origin xyz="0.0 0.0 0.00015403767"/>
      <mass value="1.8569388"/>
      <inertia ixx="0.008637359099999999" ixy="0.0" ixz="-0.0" iyy="0.0086373644" iyz="-0.0" izz="0.016376551"/>
    </inertial>
    <visual>
      <origin rpy="0.0 0.0 0.0" xyz="0.0 0.0 0.0"/>
      <geometry>
        <mesh filename="package://centauro_urdf/meshes/v2/mesh_wheel23.stl" scale="0.001 0.001 -0.001"/>
      </geometry>
      <material name="black"/>
    </visual>
    <collision>
      <origin rpy="0 0 0" xyz="0 0 0"/>
      <geometry>
        <mesh filename="package://centauro_urdf/meshes/v2/collision/mesh_wheel23.stl" scale="0.001 0.001 -0.001"/>
      </geometry>
      <material name="black"/>
    </collision>
  </link>
  <!-- *****************************-->
  <link name="contact_3"/>
  <joint name="contact_joint_3" type="fixed">
    <parent link="ankle2_3"/>
    <child link="contact_3"/>
    <origin rpy="0 0 0" xyz="0 0 -0.176"/>
  </joint>
  <!-- ******************************** -->
  <joint name="hip_yaw_3" type="revolute">
    <parent link="pelvis"/>
    <child link="hip1_3"/>
    <origin rpy="0.0 0.0 0.0" xyz="-0.25 0.125 -0.056600000000000004"/>
    <axis xyz="0 0 -1"/>
    <limit effort="304" lower="-2.51" upper="2.03" velocity="8.8"/>
    <!-- 200 Nm, 1 rad/s-->
  </joint>
  <joint name="hip_pitch_3" type="revolute">
    <parent link="hip1_3"/>
    <child link="hip2_3"/>
    <origin rpy="1.57079632679 0.0 0.0" xyz="0.0 0.1146 -0.0625"/>
    <axis xyz="0 0 -1"/>
    <limit effort="304" lower="-2.0126" upper="2.0384" velocity="8.8"/>
    <!-- 200 Nm, 1 rad/s-->
  </joint>
  <joint name="knee_pitch_3" type="revolute">
    <parent link="hip2_3"/>
    <child link="knee_3"/>
    <origin rpy="3.14159265359 0.0 0.0" xyz="0.0 -0.3 0.1182"/>
    <axis xyz="0 0 -1"/>
    <limit effort="304" lower="-2.4056" upper="2.4064" velocity="8.8"/>
    <!-- 200 Nm, 1 rad/s-->
  </joint>
  <joint name="ankle_pitch_3" type="revolute">
    <parent link="knee_3"/>
    <child link="ankle1_3"/>
    <origin rpy="3.14159265359 0.0 0.0" xyz="0.0 0.2 0.10015"/>
    <axis xyz="0 0 -1"/>
    <limit effort="147" lower="-2.4696" upper="2.4464" velocity="8.1"/>
    <!-- 98 Nm, 1 rad/s-->
  </joint>
  <joint name="ankle_yaw_3" type="revolute">
    <parent link="ankle1_3"/>
    <child link="ankle2_3"/>
    <origin rpy="-1.57079632679 0.0 0.0" xyz="0.0 -0.139 -0.00085"/>
    <axis xyz="0 0 -1"/>
    <limit effort="35" lower="-2.5606" upper="2.5454" velocity="20.0"/>
    <!-- 23 Nm, 1 rad/s-->
  </joint>
  <link name="hip1_4">
    <inertial>
      <origin xyz="0.0003595855 -0.033338818000000006 -0.059190309"/>
      <mass value="2.3349153"/>
      <!-- org: 2 -->
      <inertia ixx="0.0068405374" ixy="-1.8572633e-05" ixz="-4.8325972e-05" iyy="0.0026261815" iyz="-0.0001564273" izz="0.0066933354"/>
    </inertial>
    <visual>
      <origin rpy="0.0 0.0 0.0" xyz="0.0 0.0 0.0"/>
      <geometry>
        <mesh filename="package://centauro_urdf/meshes/v2/hip-yaw.stl" scale="0.001 0.001 0.001"/>
      </geometry>
      <material name="dark_grey"/>
    </visual>
    <collision>
      <origin rpy="0.0 0.0 0.0" xyz="0.0 0.0 0.0"/>
      <geometry>
        <mesh filename="package://centauro_urdf/meshes/v2/collision/hip-yaw.stl" scale="0.001 0.001 0.001"/>
      </geometry>
    </collision>
  </link>
  <link name="hip2_4">
    <inertial>
      <origin xyz="-4.6285952e-06 -0.2214019 -0.03316685"/>
      <mass value="3.4572118"/>
      <!-- org: 4.5 -->
      <inertia ixx="0.050469853" ixy="-7.784938699999999e-06" ixz="9.220580999999999e-06" iyy="0.008181596999999999" iyz="-0.0059796848" izz="0.048213808999999996"/>
    </inertial>
    <visual>
      <origin rpy="0.0 0.0 0.0" xyz="0.0 0.0 0.0"/>
      <geometry>
        <mesh filename="package://centauro_urdf/meshes/v2/hip-pitch.stl" scale="0.001 0.001 0.001"/>
      </geometry>
    </visual>
    <collision>
      <origin rpy="0.0 0.0 0.0" xyz="0.0 0.0 0.0"/>
      <geometry>
        <mesh filename="package://centauro_urdf/meshes/v2/collision/hip-pitch.stl" scale="0.001 0.001 0.001"/>
      </geometry>
    </collision>
  </link>
  <link name="knee_4">
    <inertial>
      <origin xyz="0.00012063381 0.14620674 -0.029740711000000003"/>
      <mass value="2.1199315"/>
      <!-- org: 3.5, foot un modeled-->
      <inertia ixx="0.018426402999999997" ixy="2.8226635999999997e-05" ixz="2.9204348e-05" iyy="0.0047685615" iyz="0.002640771" izz="0.017793722"/>
    </inertial>
    <visual>
      <origin rpy="0.0 0.0 0.0" xyz="0.0 0.0 0.0"/>
      <geometry>
        <mesh filename="package://centauro_urdf/meshes/v2/knee.stl" scale="0.001 0.001 0.001"/>
      </geometry>
      <material name="dark_grey"/>
    </visual>
    <collision>
      <origin rpy="0.0 0.0 0.0" xyz="0.0 0.0 0.0"/>
      <geometry>
        <mesh filename="package://centauro_urdf/meshes/v2/collision/knee.stl" scale="0.001 0.001 0.001"/>
      </geometry>
    </collision>
  </link>
  <link name="ankle1_4">
    <inertial>
      <origin xyz="0.00012360094 -0.06274712 0.0049068453"/>
      <mass value="1.4023368"/>
      <!-- org: 3.5, foot un modeled-->
      <inertia ixx="0.0049928829" ixy="5.762355699999999e-06" ixz="-1.9606394e-05" iyy="0.0017621464" iyz="-0.00045315091" izz="0.0048706328"/>
    </inertial>
    <visual>
      <origin rpy="0.0 0.0 0.0" xyz="0.0 0.0 0.0"/>
      <geometry>
        <mesh filename="package://centauro_urdf/meshes/v2/ankle-pitch.stl" scale="0.001 0.001 0.001"/>
      </geometry>
    </visual>
    <collision>
      <origin rpy="0.0 0.0 0.0" xyz="0.0 0.0 0.0"/>
      <geometry>
        <mesh filename="package://centauro_urdf/meshes/v2/collision/ankle-pitch.stl" scale="0.001 0.001 0.001"/>
      </geometry>
    </collision>
  </link>
  <link name="ankle2_4">
    <inertial>
      <origin xyz="0.00018512273 -0.0017369405000000001 -0.091340683"/>
      <mass value="2.440929"/>
      <!-- org: 3.5, foot un modeled-->
      <inertia ixx="0.017711499" ixy="-1.0713141e-05" ixz="-2.2094697e-05" iyy="0.014263485" iyz="-0.00033426702" izz="0.0080747557"/>
    </inertial>
    <visual>
      <origin rpy="0.0 0.0 0.0" xyz="0.0 0.0 0.0"/>
      <geometry>
        <mesh filename="package://centauro_urdf/meshes/v2/mesh_ankle-yaw_wheel23.stl" scale="0.001 0.001 0.001"/>
      </geometry>
      <material name="dark_grey"/>
    </visual>
    <collision>
      <origin rpy="0.0 0.0 0.0" xyz="0.0 0.0 0.0"/>
      <geometry>
        <mesh filename="package://centauro_urdf/meshes/v2/collision/mesh_ankle-yaw_wheel23.stl" scale="0.001 0.001 0.001"/>
      </geometry>
    </collision>
  </link>
  <joint name="j_wheel_4" type="continuous">
    <parent link="ankle2_4"/>
    <child link="wheel_4"/>
    <origin rpy="1.57079632679 0.0 0.0" xyz="0.0 0.0 -0.14435"/>
    <axis xyz="0 0 1"/>
    <limit effort="35" velocity="20.0"/>
    <!-- 23 Nm, 1
            rad/s-->
  </joint>
  <link name="wheel_4">
    <inertial>
      <origin xyz="0.0 0.0 -0.00015403767"/>
      <mass value="1.8569388"/>
      <inertia ixx="0.008637359099999999" ixy="0.0" ixz="0.0" iyy="0.0086373644" iyz="0.0" izz="0.016376551"/>
    </inertial>
    <visual>
      <origin rpy="0.0 0.0 0.0" xyz="0.0 0.0 0.0"/>
      <geometry>
        <mesh filename="package://centauro_urdf/meshes/v2/mesh_wheel23.stl" scale="0.001 0.001 0.001"/>
      </geometry>
      <material name="black"/>
    </visual>
    <collision>
      <origin rpy="0 0 0" xyz="0 0 0"/>
      <geometry>
        <mesh filename="package://centauro_urdf/meshes/v2/collision/mesh_wheel23.stl" scale="0.001 0.001 0.001"/>
      </geometry>
      <material name="black"/>
    </collision>
  </link>
  <!-- *****************************-->
  <link name="contact_4"/>
  <joint name="contact_joint_4" type="fixed">
    <parent link="ankle2_4"/>
    <child link="contact_4"/>
    <origin rpy="0 0 0" xyz="0 0 -0.176"/>
  </joint>
  <!-- ******************************** -->
  <joint name="hip_yaw_4" type="revolute">
    <parent link="pelvis"/>
    <child link="hip1_4"/>
    <origin rpy="0.0 0.0 0.0" xyz="-0.25 -0.125 -0.056600000000000004"/>
    <axis xyz="0 0 -1"/>
    <limit effort="304" lower="-2.03" upper="2.51" velocity="8.8"/>
    <!-- 200 Nm, 1 rad/s-->
  </joint>
  <joint name="hip_pitch_4" type="revolute">
    <parent link="hip1_4"/>
    <child link="hip2_4"/>
    <origin rpy="1.57079632679 0.0 0.0" xyz="0.0 -0.1146 -0.0625"/>
    <axis xyz="0 0 1"/>
    <limit effort="304" lower="-2.0326" upper="2.0524" velocity="8.8"/>
    <!-- 200 Nm, 1 rad/s-->
  </joint>
  <joint name="knee_pitch_4" type="revolute">
    <parent link="hip2_4"/>
    <child link="knee_4"/>
    <origin rpy="3.14159265359 0.0 0.0" xyz="0.0 -0.3 -0.1182"/>
    <axis xyz="0 0 1"/>
    <limit effort="304" lower="-2.4176" upper="2.3884" velocity="8.8"/>
    <!-- 200 Nm, 1 rad/s-->
  </joint>
  <joint name="ankle_pitch_4" type="revolute">
    <parent link="knee_4"/>
    <child link="ankle1_4"/>
    <origin rpy="3.14159265359 0.0 0.0" xyz="0.0 0.2 -0.10015"/>
    <axis xyz="0 0 1"/>
    <limit effort="147" lower="-2.3426" upper="2.3934" velocity="8.1"/>
    <!-- 98 Nm, 1 rad/s-->
  </joint>
  <joint name="ankle_yaw_4" type="revolute">
    <parent link="ankle1_4"/>
    <child link="ankle2_4"/>
    <origin rpy="-1.57079632679 0.0 0.0" xyz="0.0 -0.139 0.00085"/>
    <axis xyz="0 0 -1"/>
    <limit effort="35" lower="-2.6046" upper="2.5514" velocity="20.0"/>
    <!-- 23 Nm, 1 rad/s-->
  </joint>
  <!-- ************ Control frames ************ -->
  <link name="world"/>
  <joint name="reference" type="floating">
    <parent link="world"/>
    <child link="pelvis"/>
  </joint>
  <!-- car frame virtual joints -->
  <joint name="car_frame_tx" type="prismatic">
    <parent link="pelvis"/>
    <origin xyz="0.0 0.0 0.0"/>
    <child link="car_frame_intermediate_1"/>
    <axis xyz="1 0 0"/>
    <limit effort="1000" lower="-1e9" upper="1e9" velocity="10.0"/>
  </joint>
  <link name="car_frame_intermediate_1">
    <inertial>
      <mass value="0.0"/>
      <inertia ixx="0.0" ixy="0.0" ixz="0.0" iyy="0.0" iyz="0.0" izz="0.0"/>
    </inertial>
  </link>
  <joint name="car_frame_ty" type="prismatic">
    <parent link="car_frame_intermediate_1"/>
    <origin xyz="0.0 0.0 0.0"/>
    <child link="car_frame_intermediate_2"/>
    <axis xyz="0 1 0"/>
    <limit effort="1000" lower="-1e9" upper="1e9" velocity="10.0"/>
  </joint>
  <link name="car_frame_intermediate_2">
    <inertial>
      <mass value="0.0"/>
      <inertia ixx="0.0" ixy="0.0" ixz="0.0" iyy="0.0" iyz="0.0" izz="0.0"/>
    </inertial>
  </link>
  <joint name="car_frame_tz" type="prismatic">
    <parent link="car_frame_intermediate_2"/>
    <origin xyz="0.0 0.0 0.0"/>
    <child link="car_frame_intermediate_3"/>
    <axis xyz="0 0 1"/>
    <limit effort="1000" lower="-1e9" upper="1e9" velocity="10.0"/>
  </joint>
  <link name="car_frame_intermediate_3">
    <inertial>
      <mass value="0.0"/>
      <inertia ixx="0.0" ixy="0.0" ixz="0.0" iyy="0.0" iyz="0.0" izz="0.0"/>
    </inertial>
  </link>
  <joint name="car_frame_rx" type="revolute">
    <parent link="car_frame_intermediate_3"/>
    <origin xyz="0.0 0.0 0.0"/>
    <child link="car_frame_intermediate_4"/>
    <axis xyz="1 0 0"/>
    <limit effort="1000" lower="-1e9" upper="1e9" velocity="10.0"/>
  </joint>
  <link name="car_frame_intermediate_4">
    <inertial>
      <mass value="0.0"/>
      <inertia ixx="0.0" ixy="0.0" ixz="0.0" iyy="0.0" iyz="0.0" izz="0.0"/>
    </inertial>
  </link>
  <joint name="car_frame_ry" type="revolute">
    <parent link="car_frame_intermediate_4"/>
    <origin xyz="0.0 0.0 0.0"/>
    <child link="car_frame_intermediate_5"/>
    <axis xyz="0 1 0"/>
    <limit effort="1000" lower="-1e9" upper="1e9" velocity="10.0"/>
  </joint>
  <link name="car_frame_intermediate_5">
    <inertial>
      <mass value="0.0"/>
      <inertia ixx="0.0" ixy="0.0" ixz="0.0" iyy="0.0" iyz="0.0" izz="0.0"/>
    </inertial>
  </link>
  <joint name="car_frame_rz" type="revolute">
    <parent link="car_frame_intermediate_5"/>
    <origin xyz="0.0 0.0 0.0"/>
    <child link="car_frame"/>
    <axis xyz="0 0 1"/>
    <limit effort="1000" lower="-1e9" upper="1e9" velocity="10.0"/>
  </joint>
  <link name="car_frame">
    <inertial>
      <mass value="0.0"/>
      <inertia ixx="0.0" ixy="0.0" ixz="0.0" iyy="0.0" iyz="0.0" izz="0.0"/>
    </inertial>
  </link>
</robot>
