<mujoco model="centauro">
    <compiler angle="radian" />
    <asset>
        <texture type="skybox" builtin="gradient" rgb1=".3 .5 .7" rgb2="0 0 0" width="512" height="512"/>
        <texture name="body" type="cube" builtin="flat" mark="cross" width="127" height="1278" rgb1="0.8 0.6 0.4" rgb2="0.8 0.6 0.4" markrgb="1 1 1" random="0.01"/>
        <material name="body" texture="body" texuniform="true" rgba="0.8 0.6 .4 1"/>
        <texture name="grid" type="2d" builtin="checker" width="512" height="512" rgb1=".1 .2 .3" rgb2=".2 .3 .4"/>
        <material name="grid" texture="grid" texrepeat="1 1" texuniform="true" reflectance=".2"/>
    </asset>
    <option timestep="0.0005"/>
    <size njmax="1000" nconmax="200"/>
    <worldbody>
        <geom name="floor" size="0 0 .05" pos="0 0 -0.10" type="plane" material="grid" condim="3"/>
        <light name="spotlight" mode="targetbodycom" target="pelvis" diffuse=".8 .8 .8" specular="0.3 0.3 0.3" pos="0 -20 4" cutoff="10"/>
        <body name="pelvis" pos="0 0 1.0">
            <inertial pos="0.00490056 0.0029738 0.0781582" quat="0.043468 0.71861 0.0206273 0.693747" mass="27.2166" diaginertia="1.12235 1.0509 0.395597" />
            <joint name="reference" type="free" />
            <geom conaffinity="0" size="0.213204 0.192971" pos="-0.005085 2.00284e-07 0.0305795" quat="0.698956 1.30282e-07 0.715165 -1.10029e-12" type="cylinder" />
            <geom conaffinity="0" size="0.213204" pos="-0.198005 0 0.035003" quat="0.698956 1.30282e-07 0.715165 -1.10029e-12" />
            <geom conaffinity="0" size="0.213204" pos="0.187835 0 0.026156" quat="0.698956 1.30282e-07 0.715165 -1.10029e-12" />
            <geom conaffinity="0" size="0.012525 0.045 0.0125" pos="0.278137 0 0.0324153" quat="0.965725 0 0.259569 0" type="box" />
            <geom conaffinity="0" size="0.0142751 0.0511264" pos="0.286046 -0.0005815 0.0630072" quat="0.00361171 0.00532006 -0.706237 -0.707946" type="cylinder" />
            <geom conaffinity="0" size="0.0142751" pos="0.286692 -0.051704 0.062884" quat="0.00361171 0.00532006 -0.706237 -0.707946" />
            <geom conaffinity="0" size="0.0142751" pos="0.2854 0.050541 0.06313" quat="0.00361171 0.00532006 -0.706237 -0.707946" />
            <body name="torso_2" pos="0.2 0 0.256">
                <inertial pos="-0.0189049 0.00457459 0.138217" quat="0.705478 0.707988 0.0227914 -0.0231079" mass="12.8925" diaginertia="0.0642204 0.0480334 0.0272949" />
                <joint name="torso_yaw" pos="0 0 0" axis="0 0 1" limited="true" range="-2.618 2.618" />
                <geom conaffinity="0" size="0.158224 0.0477184" pos="-3.2165e-05 9.785e-05 0.0746528" quat="0.708575 0.705547 -0.0112062 0" type="cylinder" />
                <geom conaffinity="0" size="0.158224" pos="0.000726 0.04781 0.074454" quat="0.708575 0.705547 -0.0112062 0" />
                <geom conaffinity="0" size="0.158224" pos="-0.00079 -0.047614 0.074851" quat="0.708575 0.705547 -0.0112062 0" />
                <geom conaffinity="0" size="0.100414 0.0822705" pos="0.00956185 0.00615924 0.312422" quat="0.982675 0.000102429 0.185339 0" type="cylinder" />
                <geom conaffinity="0" size="0.100414" pos="-0.0204053 0.00617572 0.235803" quat="0.982675 0.000102429 0.185339 0" />
                <geom conaffinity="0" size="0.100414" pos="0.0395297 0.00614272 0.38904" quat="0.982675 0.000102429 0.185339 0" />
                <body name="arm1_1" pos="0.0457475 0.169137 0.116626" quat="0.96225 0.084186 -0.0225576 -0.257834">
                    <inertial pos="-0.00744572 0.034108 0.000109781" quat="0.461563 0.54214 -0.445839 0.542467" mass="1.96287" diaginertia="0.00689332 0.0054198 0.00332613" />
                    <joint name="j_arm1_1" pos="0 0 0" axis="0 1 0" limited="true" range="-3.312 1.615" />
                    <geom conaffinity="0" size="0.0698859 0.0186988" pos="0.0178314 0.0532412 2.3169e-05" quat="0.702119 -0.0833415 0.707165 1.89504e-12" type="cylinder" />
                    <geom conaffinity="0" size="0.0698859" pos="-0.000737 0.051053 0.000286" quat="0.702119 -0.0833415 0.707165 1.89504e-12" />
                    <geom conaffinity="0" size="0.0698859" pos="0.0364 0.05543 -0.00024" quat="0.702119 -0.0833415 0.707165 1.89504e-12" />
                    <body name="arm1_2" pos="-0.09015 0.062 0" quat="0.996195 -0.0871556 0 0">
                        <inertial pos="0.0581423 5.74508e-05 -0.0774777" quat="0.716914 -0.118275 -0.124187 0.675739" mass="1.85958" diaginertia="0.0156794 0.0151279 0.00327857" />
                        <joint name="j_arm1_2" pos="0 0 0" axis="1 0 0" limited="true" range="0.02 3.431" ref="-0.5" />
                        <geom conaffinity="0" size="0.0700645 0.0639963" pos="0.0637382 4.038e-07 -0.0643592" quat="0.213415 2.39454e-05 0.976962 0" type="cylinder" />
                        <geom conaffinity="0" size="0.0700645" pos="0.037052 1e-06 -0.006192" quat="0.213415 2.39454e-05 0.976962 0" />
                        <geom conaffinity="0" size="0.0700645" pos="0.090424 0 -0.122526" quat="0.213415 2.39454e-05 0.976962 0" />
                        <body name="arm1_3" pos="0.09015 0 -0.21815">
                            <inertial pos="0.0146252 0.000817267 -0.0283335" quat="0.603634 -0.131469 -0.12394 0.776518" mass="1.66781" diaginertia="0.00737031 0.00688019 0.0032086" />
                            <joint name="j_arm1_3" pos="0 0 0" axis="0 0 1" limited="true" range="-2.552 2.566" />
                            <geom conaffinity="0" size="0.0896121 0.0304113" pos="0.00730754 -0.00409114 -0.0366288" quat="0.13918 0.483716 0.864088 1.18459e-12" type="cylinder" />
                            <geom conaffinity="0" size="0.0896121" pos="-7e-06 4e-06 -0.007396" quat="0.13918 0.483716 0.864088 1.18459e-12" />
                            <geom conaffinity="0" size="0.0896121" pos="0.014622 -0.008186 -0.065862" quat="0.13918 0.483716 0.864088 1.18459e-12" />
                            <body name="arm1_4" pos="0.045 0.05515 -0.074">
                                <inertial pos="-0.00768331 -0.0403022 -0.0434928" quat="0.983894 -0.157573 0.0796967 0.027782" mass="1.31573" diaginertia="0.0043973 0.0041202 0.00142636" />
                                <joint name="j_arm1_4" pos="0 0 0" axis="0 1 0" limited="true" range="-2.465 0.28" />
                                <geom conaffinity="0" size="0.0600429 0.0435671" pos="-0.0074602 -0.0408499 -0.0404292" quat="0.982114 -0.166547 0.0878262 0" type="cylinder" />
                                <geom conaffinity="0" size="0.0600429" pos="-0.014976 -0.055102 -0.080907" quat="0.982114 -0.166547 0.0878262 0" />
                                <geom conaffinity="0" size="0.0600429" pos="5.6e-05 -0.026598 4.9e-05" quat="0.982114 -0.166547 0.0878262 0" />
                                <body name="arm1_5" pos="-0.015 -0.05515 -0.095">
                                    <inertial pos="-0.000110796 0.0115908 -0.0781603" quat="0.999411 -0.0326811 -0.00141582 0.0103607" mass="1.49085" diaginertia="0.00856963 0.00776657 0.00272262" />
                                    <joint name="j_arm1_5" pos="0 0 0" axis="0 0 1" limited="true" range="-2.569 2.562" />
                                    <geom conaffinity="0" size="0.0804108 0.0421737" pos="-3.79828e-06 0.00576208 -0.082271" quat="0.995248 -0.0973705 5.47455e-05 0" type="cylinder" />
                                    <geom conaffinity="0" size="0.0804108" pos="-8e-06 -0.002412 -0.123645" quat="0.995248 -0.0973705 5.47455e-05 0" />
                                    <geom conaffinity="0" size="0.0804108" pos="1e-06 0.013936 -0.040897" quat="0.995248 -0.0973705 5.47455e-05 0" />
                                    <body name="arm1_6" pos="0 0.049 -0.156">
                                        <inertial pos="-4.65024e-06 -0.0380141 -0.0699269" quat="0.993852 -0.0968797 0.00427602 0.0534179" mass="1.12636" diaginertia="0.00519002 0.00494291 0.00113517" />
                                        <joint name="j_arm1_6" pos="0 0 0" axis="0 1 0" limited="true" range="-1.529 1.509" />
                                        <geom conaffinity="0" size="0.0583263 0.0571257" pos="1.10955e-06 -0.0434554 -0.0574973" quat="0.996962 -0.0778833 -0.000322529 0" type="cylinder" />
                                        <geom conaffinity="0" size="0.0583263" pos="3.8e-05 -0.052327 -0.11393" quat="0.996962 -0.0778833 -0.000322529 0" />
                                        <geom conaffinity="0" size="0.0583263" pos="-3.6e-05 -0.034584 -0.001065" quat="0.996962 -0.0778833 -0.000322529 0" />
                                        <body name="arm1_7" pos="0 -0.049 -0.174">
                                            <inertial pos="9.48576e-06 0.000541461 0.01433" quat="0.536054 0.460309 -0.42533 0.565558" mass="1.92794" diaginertia="0.00341793 0.00316235 0.00311839" />
                                            <joint name="j_arm1_7" pos="0 0 0" axis="0 0 1" limited="true" range="-2.565 2.569" />
                                            <geom conaffinity="0" size="0.0207073 0.00458365" pos="0 0 0.0101335" quat="0.707107 -0.682842 -0.18365 0" type="cylinder" />
                                            <geom conaffinity="0" size="0.0207073" pos="0.00119 -0.004426 0.010133" quat="0.707107 -0.682842 -0.18365 0" />
                                            <geom conaffinity="0" size="0.0207073" pos="-0.00119 0.004426 0.010134" quat="0.707107 -0.682842 -0.18365 0" />
                                            <geom conaffinity="0" size="0.0709883 4.97004e-05" pos="-2.682e-07 1.2015e-06 -0.0105021" quat="0.707818 -0.265302 -0.654682 0" type="cylinder" />
                                            <geom conaffinity="0" size="0.0709883" pos="4.6e-05 -1.7e-05 -0.010502" quat="0.707818 -0.265302 -0.654682 0" />
                                            <geom conaffinity="0" size="0.0709883" pos="-4.6e-05 2e-05 -0.010502" quat="0.707818 -0.265302 -0.654682 0" />
                                        </body>
                                    </body>
                                </body>
                            </body>
                        </body>
                    </body>
                </body>
                <body name="arm2_1" pos="0.0457475 -0.169137 0.116626" quat="0.96225 -0.084186 -0.0225576 0.257834">
                    <inertial pos="-0.00744572 -0.034108 0.000109781" quat="0.54214 0.461563 -0.542467 0.445839" mass="1.96287" diaginertia="0.00689332 0.0054198 0.00332613" />
                    <joint name="j_arm2_1" pos="0 0 0" axis="0 1 0" limited="true" range="-3.3458 1.6012" />
                    <geom conaffinity="0" size="0.0698859 0.0186988" pos="0.0178314 -0.0532412 2.3169e-05" quat="0.702119 0.0833415 0.707165 -1.89504e-12" type="cylinder" />
                    <geom conaffinity="0" size="0.0698859" pos="-0.000737 -0.051053 0.000286" quat="0.702119 0.0833415 0.707165 -1.89504e-12" />
                    <geom conaffinity="0" size="0.0698859" pos="0.0364 -0.05543 -0.00024" quat="0.702119 0.0833415 0.707165 -1.89504e-12" />
                    <body name="arm2_2" pos="-0.09015 -0.062 0" quat="0.996195 0.0871556 0 0">
                        <inertial pos="0.0581423 -5.74508e-05 -0.0774777" quat="0.675739 -0.124187 -0.118275 0.716914" mass="1.85958" diaginertia="0.0156794 0.0151279 0.00327857" />
                        <joint name="j_arm2_2" pos="0 0 0" axis="1 0 0" limited="true" range="-3.4258 -0.0138" ref="0.50" />
                        <geom conaffinity="0" size="0.0700645 0.0639963" pos="0.0637382 -4.038e-07 -0.0643592" quat="0.213415 -2.39454e-05 0.976962 0" type="cylinder" />
                        <geom conaffinity="0" size="0.0700645" pos="0.037052 -1e-06 -0.006192" quat="0.213415 -2.39454e-05 0.976962 0" />
                        <geom conaffinity="0" size="0.0700645" pos="0.090424 0 -0.122526" quat="0.213415 -2.39454e-05 0.976962 0" />
                        <body name="arm2_3" pos="0.09015 0 -0.21815">
                            <inertial pos="0.0146252 -0.000817267 -0.0283335" quat="0.776518 -0.12394 -0.131469 0.603634" mass="1.66781" diaginertia="0.00737031 0.00688019 0.0032086" />
                            <joint name="j_arm2_3" pos="0 0 0" axis="0 0 1" limited="true" range="-2.5614 2.5606" />
                            <geom conaffinity="0" size="0.0896121 0.0304113" pos="0.00730754 0.00409114 -0.0366288" quat="0.13918 -0.483716 0.864088 -1.18459e-12" type="cylinder" />
                            <geom conaffinity="0" size="0.0896121" pos="-7e-06 -4e-06 -0.007396" quat="0.13918 -0.483716 0.864088 -1.18459e-12" />
                            <geom conaffinity="0" size="0.0896121" pos="0.014622 0.008186 -0.065862" quat="0.13918 -0.483716 0.864088 -1.18459e-12" />
                            <body name="arm2_4" pos="0.045 -0.05515 -0.074">
                                <inertial pos="-0.00768331 0.0403022 -0.0434928" quat="0.983894 0.157573 0.0796967 -0.027782" mass="1.31573" diaginertia="0.0043973 0.0041202 0.00142636" />
                                <joint name="j_arm2_4" pos="0 0 0" axis="0 1 0" limited="true" range="-2.4794 0.2886" />
                                <geom conaffinity="0" size="0.0600429 0.0435671" pos="-0.0074602 0.0408499 -0.0404292" quat="0.982114 0.166547 0.0878262 0" type="cylinder" />
                                <geom conaffinity="0" size="0.0600429" pos="-0.014976 0.055102 -0.080907" quat="0.982114 0.166547 0.0878262 0" />
                                <geom conaffinity="0" size="0.0600429" pos="5.6e-05 0.026598 4.9e-05" quat="0.982114 0.166547 0.0878262 0" />
                                <body name="arm2_5" pos="-0.015 0.05515 -0.095">
                                    <inertial pos="-0.000110796 -0.0115908 -0.0781603" quat="0.999411 0.0326811 -0.00141582 -0.0103607" mass="1.49085" diaginertia="0.00856963 0.00776657 0.00272262" />
                                    <joint name="j_arm2_5" pos="0 0 0" axis="0 0 1" limited="true" range="-2.5394 2.5546" />
                                    <geom conaffinity="0" size="0.0804108 0.0421737" pos="-3.79828e-06 -0.00576208 -0.082271" quat="0.995248 0.0973705 5.47455e-05 0" type="cylinder" />
                                    <geom conaffinity="0" size="0.0804108" pos="-8e-06 0.002412 -0.123645" quat="0.995248 0.0973705 5.47455e-05 0" />
                                    <geom conaffinity="0" size="0.0804108" pos="1e-06 -0.013936 -0.040897" quat="0.995248 0.0973705 5.47455e-05 0" />
                                    <body name="arm2_6" pos="0 -0.049 -0.156">
                                        <inertial pos="-4.65024e-06 0.0380141 -0.0699269" quat="0.993852 0.0968797 0.00427602 -0.0534179" mass="1.12636" diaginertia="0.00519002 0.00494291 0.00113517" />
                                        <joint name="j_arm2_6" pos="0 0 0" axis="0 1 0" limited="true" range="-1.5154 1.5156" />
                                        <geom conaffinity="0" size="0.0583263 0.0571257" pos="1.10955e-06 0.0434554 -0.0574973" quat="0.996962 0.0778833 -0.000322529 0" type="cylinder" />
                                        <geom conaffinity="0" size="0.0583263" pos="3.8e-05 0.052327 -0.11393" quat="0.996962 0.0778833 -0.000322529 0" />
                                        <geom conaffinity="0" size="0.0583263" pos="-3.6e-05 0.034584 -0.001065" quat="0.996962 0.0778833 -0.000322529 0" />
                                        <body name="arm2_7" pos="0 0.049 -0.174">
                                            <inertial pos="9.48576e-06 -0.000491936 0.01433" quat="0.457705 0.538036 -0.562311 0.429918" mass="1.92794" diaginertia="0.00341759 0.00316238 0.0031189" />
                                            <joint name="j_arm2_7" pos="0 0 0" axis="0 0 1" limited="true" range="-2.5554 2.5686" />
                                            <geom conaffinity="0" size="0.0207073 0.00458365" pos="0 0 0.0101335" quat="0.707107 0.682842 -0.18365 0" type="cylinder" />
                                            <geom conaffinity="0" size="0.0207073" pos="0.00119 0.004426 0.010133" quat="0.707107 0.682842 -0.18365 0" />
                                            <geom conaffinity="0" size="0.0207073" pos="-0.00119 -0.004426 0.010134" quat="0.707107 0.682842 -0.18365 0" />
                                            <geom conaffinity="0" size="0.0709883 4.97004e-05" pos="-2.682e-07 1.2015e-06 -0.0105021" quat="0.707818 -0.265302 -0.654682 0" type="cylinder" />
                                            <geom conaffinity="0" size="0.0709883" pos="4.6e-05 -1.7e-05 -0.010502" quat="0.707818 -0.265302 -0.654682 0" />
                                            <geom conaffinity="0" size="0.0709883" pos="-4.6e-05 2e-05 -0.010502" quat="0.707818 -0.265302 -0.654682 0" />
                                        </body>
                                    </body>
                                </body>
                            </body>
                        </body>
                    </body>
                </body>
                <body name="velodyne_motor" pos="0.0853361 0.00616072 0.4">
                    <inertial pos="0 0 0.0255623" quat="0.594705 0.741161 0.0512412 -0.307215" mass="1.17879" diaginertia="0.00164255 0.00159806 0.00136504" />
                    <joint name="velodyne_joint" pos="0 0 0" axis="0 -1 0" limited="true" range="-1.1 1.1" frictionloss="10" />
                    <geom conaffinity="0" size="0.0544637 0.0162316" pos="-0.000743872 0.00508305 0.00835998" quat="0.710282 -0.701573 -0.0573979 0" type="cylinder" />
                    <geom conaffinity="0" size="0.0544637" pos="0.00058 -0.011094 0.008214" quat="0.710282 -0.701573 -0.0573979 0" />
                    <geom conaffinity="0" size="0.0544637" pos="-0.002067 0.02126 0.008506" quat="0.710282 -0.701573 -0.0573979 0" />
                    <geom conaffinity="0" size="0.0516 0.03585" pos="0 0 0.03585" type="cylinder" />
                    <geom conaffinity="0" size="0.0516" />
                    <geom conaffinity="0" size="0.0516" pos="0 0 0.0717" />
                </body>
                <body name="d435_head_motor" pos="0.0630637 0.00616072 0.2955">
                    <inertial pos="0.0188357 0.0109328 0" quat="0.492029 0.4631 -0.536475 0.505609" mass="0.902787" diaginertia="0.00464125 0.00432785 0.00086765" />
                    <joint name="d435_head_joint" pos="0 0 0" axis="0 -1 0" limited="true" range="-1.1 1.1" frictionloss="10" />
                    <geom conaffinity="0" size="0.0261699 0.0606721" pos="0.0155365 -0.0046848 0.00250922" quat="0.697856 -0.715488 0.0327707 0" type="cylinder" />
                    <geom conaffinity="0" size="0.0261699" pos="0.012761 -0.065273 0.004086" quat="0.697856 -0.715488 0.0327707 0" />
                    <geom conaffinity="0" size="0.0261699" pos="0.018311 0.055903 0.000932" quat="0.697856 -0.715488 0.0327707 0" />
                    <geom conaffinity="0" size="0.012525 0.045 0.0125" pos="0.03015 0 0" type="box" />
                </body>
            </body>
            <body name="hip1_1" pos="0.25 0.125 -0.0566">
                <inertial pos="0.000359586 0.0333388 -0.0591903" quat="0.712917 0.685529 0.104088 -0.104718" mass="2.33492" diaginertia="0.00685516 0.00668482 0.00262008" />
                <joint name="hip_yaw_1" pos="0 0 0" axis="0 0 -1" limited="true" range="-2.03 2.51" />
                <geom conaffinity="0" size="0.0747223 0.0153477" pos="0.000123454 -0.0119497 -0.0631367" quat="0.802262 -0.596933 0.00689249 0" type="cylinder" />
                <geom conaffinity="0" size="0.0747223" pos="-4.6e-05 -0.02665 -0.067545" quat="0.802262 -0.596933 0.00689249 0" />
                <geom conaffinity="0" size="0.0747223" pos="0.000293 0.00275 -0.058728" quat="0.802262 -0.596933 0.00689249 0" />
                <body name="hip2_1" pos="0 0.1146 -0.0625" quat="0.707107 0.707107 0 0">
                    <inertial pos="-4.6286e-06 -0.221402 0.0331668" quat="0.756514 0.653967 0.00236922 -0.00285355" mass="3.45721" diaginertia="0.0504699 0.0490878 0.00730749" />
                    <joint name="hip_pitch_1" pos="0 0 0" axis="0 0 -1" limited="true" range="-2.0226 2.02748" />
                    <geom conaffinity="0" size="0.0808941 0.14599" pos="1.10697e-06 -0.13974 0.0170087" quat="0.699955 -0.714186 -5.17577e-06 0" type="cylinder" />
                    <geom conaffinity="0" size="0.0808941" pos="2e-06 -0.285701 0.019947" quat="0.699955 -0.714186 -5.17577e-06 0" />
                    <geom conaffinity="0" size="0.0808941" pos="0 0.00622 0.014071" quat="0.699955 -0.714186 -5.17577e-06 0" />
                    <body name="knee_1" pos="0 -0.3 0.1182" quat="0 1 0 0">
                        <inertial pos="0.000120634 0.146207 0.0297407" quat="0.630451 0.765124 0.101469 -0.0825892" mass="2.11993" diaginertia="0.0184356 0.0182996 0.00425349" />
                        <joint name="knee_pitch_1" pos="0 0 0" axis="0 0 -1" limited="true" range="-2.4056 2.3994" />
                        <geom conaffinity="0" size="0.0664305 0.0963751" pos="-4.07652e-06 0.0958646 0.0143745" quat="0.69343 -0.720524 -2.92114e-05 0" type="cylinder" />
                        <geom conaffinity="0" size="0.0664305" pos="0 -0.00044 0.018066" quat="0.69343 -0.720524 -2.92114e-05 0" />
                        <geom conaffinity="0" size="0.0664305" pos="-8e-06 0.192169 0.010683" quat="0.69343 -0.720524 -2.92114e-05 0" />
                        <body name="ankle1_1" pos="0 0.2 0.10015" quat="0 1 0 0">
                            <inertial pos="0.000123601 -0.0627471 -0.00490685" quat="0.746546 0.647602 -0.0996407 0.115551" mass="1.40234" diaginertia="0.00499928 0.00492895 0.00169743" />
                            <joint name="ankle_pitch_1" pos="0 0 0" axis="0 0 -1" limited="true" range="-2.4056 2.3184" />
                            <geom conaffinity="0" size="0.0792379 0.0246282" pos="-3.39946e-05 -0.0238356 -1.2084e-05" quat="0.705951 0.70826 0.000349485 0" type="cylinder" />
                            <geom conaffinity="0" size="0.0792379" pos="-4.6e-05 0.000792 6.8e-05" quat="0.705951 0.70826 0.000349485 0" />
                            <geom conaffinity="0" size="0.0792379" pos="-2.2e-05 -0.048464 -9.3e-05" quat="0.705951 0.70826 0.000349485 0" />
                            <body name="ankle2_1" pos="0 -0.139 -0.00085" quat="0.707107 -0.707107 0 0">
                                <inertial pos="0.00184967 -0.000513224 -0.0673092" quat="0.999198 0.0156728 0.0368308 -0.00100998" mass="1.76567" diaginertia="0.00741457 0.00544457 0.00428742" />
                                <joint name="ankle_yaw_1" pos="0 0 0" axis="0 0 -1" limited="true" range="-2.5626 2.5384" />
                                <geom conaffinity="0" size="0.0813545 0.0368513" pos="-1.17781e-05 -0.00182701 -0.0652808" quat="0.00125264 0.995362 0.0961939 0" type="cylinder" />
                                <geom conaffinity="0" size="0.0813545" pos="-2.1e-05 -0.001735 -0.02843" quat="0.00125264 0.995362 0.0961939 0" />
                                <geom conaffinity="0" size="0.0813545" pos="-3e-06 -0.001919 -0.102132" quat="0.00125264 0.995362 0.0961939 0" />
                                <body name="wheel_1" pos="0 0 -0.09835" quat="0.707107 0.707107 0 0">
                                    <inertial pos="0 0 -0.00311559" quat="0 0.707107 0 0.707107" mass="1.11164" diaginertia="0.00418172 0.00281756 0.00281741" />
                                    <joint name="j_wheel_1" pos="0 0 0" axis="0 0 -1" />
                                    <geom conaffinity="0" size="0.078 0.055" type="cylinder" rgba="0.4 0.4 0.4 1" />
                                    <geom conaffinity="0" size="0.078" pos="0 0 -0.055" rgba="0.4 0.4 0.4 1" />
                                    <geom conaffinity="0" size="0.078" pos="0 0 0.055" rgba="0.4 0.4 0.4 1" />
                                </body>
                            </body>
                        </body>
                    </body>
                </body>
            </body>
            <body name="hip1_2" pos="0.25 -0.125 -0.0566">
                <inertial pos="0.000359586 -0.0333388 -0.0591903" quat="0.685529 0.712917 0.104718 -0.104088" mass="2.33492" diaginertia="0.00685516 0.00668482 0.00262008" />
                <joint name="hip_yaw_2" pos="0 0 0" axis="0 0 -1" limited="true" range="-2.51 2.03" />
                <geom conaffinity="0" size="0.0747223 0.0153477" pos="0.000123454 0.0119497 -0.0631367" quat="0.802262 0.596933 0.00689249 0" type="cylinder" />
                <geom conaffinity="0" size="0.0747223" pos="-4.6e-05 0.02665 -0.067545" quat="0.802262 0.596933 0.00689249 0" />
                <geom conaffinity="0" size="0.0747223" pos="0.000293 -0.00275 -0.058728" quat="0.802262 0.596933 0.00689249 0" />
                <body name="hip2_2" pos="0 -0.1146 -0.0625" quat="0.707107 0.707107 0 0">
                    <inertial pos="-4.6286e-06 -0.221402 -0.0331668" quat="0.653967 0.756514 -0.00285355 0.00236922" mass="3.45721" diaginertia="0.0504699 0.0490878 0.00730749" />
                    <joint name="hip_pitch_2" pos="0 0 0" axis="0 0 1" limited="true" range="-2.0156 2.0354" />
                    <geom conaffinity="0" size="0.0808941 0.14599" pos="1.10697e-06 -0.13974 -0.0170087" quat="0.714186 -0.699955 -5.07264e-06 0" type="cylinder" />
                    <geom conaffinity="0" size="0.0808941" pos="2e-06 -0.285701 -0.019947" quat="0.714186 -0.699955 -5.07264e-06 0" />
                    <geom conaffinity="0" size="0.0808941" pos="0 0.00622 -0.014071" quat="0.714186 -0.699955 -5.07264e-06 0" />
                    <body name="knee_2" pos="0 -0.3 -0.1182" quat="0 1 0 0">
                        <inertial pos="0.000120634 0.146207 -0.0297407" quat="0.765124 0.630451 -0.0825892 0.101469" mass="2.11993" diaginertia="0.0184356 0.0182996 0.00425349" />
                        <joint name="knee_pitch_2" pos="0 0 0" axis="0 0 1" limited="true" range="-2.4006 2.4034" />
                        <geom conaffinity="0" size="0.0664305 0.0963751" pos="-4.07652e-06 0.0958646 -0.0143745" quat="0.720524 -0.69343 -2.8113e-05 0" type="cylinder" />
                        <geom conaffinity="0" size="0.0664305" pos="0 -0.00044 -0.018066" quat="0.720524 -0.69343 -2.8113e-05 0" />
                        <geom conaffinity="0" size="0.0664305" pos="-8e-06 0.192169 -0.010683" quat="0.720524 -0.69343 -2.8113e-05 0" />
                        <body name="ankle1_2" pos="0 0.2 -0.10015" quat="0 1 0 0">
                            <inertial pos="0.000123601 -0.0627471 0.00490685" quat="0.647602 0.746546 0.115551 -0.0996407" mass="1.40234" diaginertia="0.00499928 0.00492895 0.00169743" />
                            <joint name="ankle_pitch_2" pos="0 0 0" axis="0 0 1" limited="true" range="-2.3266 2.3914" />
                            <geom conaffinity="0" size="0.0781037 0.023942" pos="2.26075e-07 -0.0207647 0.000108892" quat="0.699852 -0.714288 0.000212448 0" type="cylinder" />
                            <geom conaffinity="0" size="0.0781037" pos="-7e-06 -0.044702 0.000598" quat="0.699852 -0.714288 0.000212448 0" />
                            <geom conaffinity="0" size="0.0781037" pos="7e-06 0.003172 -0.00038" quat="0.699852 -0.714288 0.000212448 0" />
                            <body name="ankle2_2" pos="0 -0.139 0.00085" quat="0.707107 -0.707107 0 0">
                                <inertial pos="0.00184967 0.000513224 -0.0673092" quat="0.999198 -0.0156728 0.0368308 0.00100998" mass="1.76567" diaginertia="0.00741457 0.00544457 0.00428742" />
                                <joint name="ankle_yaw_2" pos="0 0 0" axis="0 0 -1" limited="true" range="-2.5546 2.5484" />
                                <geom conaffinity="0" size="0.0813545 0.0368513" pos="-1.17781e-05 0.00182701 -0.0652808" quat="0.00125264 -0.995362 0.0961939 0" type="cylinder" />
                                <geom conaffinity="0" size="0.0813545" pos="-2.1e-05 0.001735 -0.02843" quat="0.00125264 -0.995362 0.0961939 0" />
                                <geom conaffinity="0" size="0.0813545" pos="-3e-06 0.001919 -0.102132" quat="0.00125264 -0.995362 0.0961939 0" />
                                <body name="wheel_2" pos="0 0 -0.09835" quat="0.707107 0.707107 0 0">
                                    <inertial pos="0 0 0.00311559" quat="0 0.707107 0 0.707107" mass="1.11164" diaginertia="0.00418172 0.00281756 0.00281741" />
                                    <joint name="j_wheel_2" pos="0 0 0" axis="0 0 1" />
                                    <geom conaffinity="0" size="0.078 0.055" type="cylinder" rgba="0.4 0.4 0.4 1" />
                                    <geom conaffinity="0" size="0.078" pos="0 0 -0.055" rgba="0.4 0.4 0.4 1" />
                                    <geom conaffinity="0" size="0.078" pos="0 0 0.055" rgba="0.4 0.4 0.4 1" />
                                </body>
                            </body>
                        </body>
                    </body>
                </body>
            </body>
            <body name="hip1_3" pos="-0.25 0.125 -0.0566">
                <inertial pos="0.000359586 0.0333388 -0.0591903" quat="0.712917 0.685529 0.104088 -0.104718" mass="2.33492" diaginertia="0.00685516 0.00668482 0.00262008" />
                <joint name="hip_yaw_3" pos="0 0 0" axis="0 0 -1" limited="true" range="-2.51 2.03" />
                <geom conaffinity="0" size="0.0747223 0.0153477" pos="0.000123454 -0.0119497 -0.0631367" quat="0.802262 -0.596933 0.00689249 0" type="cylinder" />
                <geom conaffinity="0" size="0.0747223" pos="-4.6e-05 -0.02665 -0.067545" quat="0.802262 -0.596933 0.00689249 0" />
                <geom conaffinity="0" size="0.0747223" pos="0.000293 0.00275 -0.058728" quat="0.802262 -0.596933 0.00689249 0" />
                <body name="hip2_3" pos="0 0.1146 -0.0625" quat="0.707107 0.707107 0 0">
                    <inertial pos="-4.6286e-06 -0.221402 0.0331668" quat="0.756514 0.653967 0.00236922 -0.00285355" mass="3.45721" diaginertia="0.0504699 0.0490878 0.00730749" />
                    <joint name="hip_pitch_3" pos="0 0 0" axis="0 0 -1" limited="true" range="-2.0126 2.0384" />
                    <geom conaffinity="0" size="0.0808941 0.14599" pos="1.10697e-06 -0.13974 0.0170087" quat="0.699955 -0.714186 -5.17577e-06 0" type="cylinder" />
                    <geom conaffinity="0" size="0.0808941" pos="2e-06 -0.285701 0.019947" quat="0.699955 -0.714186 -5.17577e-06 0" />
                    <geom conaffinity="0" size="0.0808941" pos="0 0.00622 0.014071" quat="0.699955 -0.714186 -5.17577e-06 0" />
                    <body name="knee_3" pos="0 -0.3 0.1182" quat="0 1 0 0">
                        <inertial pos="0.000120634 0.146207 0.0297407" quat="0.630451 0.765124 0.101469 -0.0825892" mass="2.11993" diaginertia="0.0184356 0.0182996 0.00425349" />
                        <joint name="knee_pitch_3" pos="0 0 0" axis="0 0 -1" limited="true" range="-2.4056 2.4064" />
                        <geom conaffinity="0" size="0.0664305 0.0963751" pos="-4.07652e-06 0.0958646 0.0143745" quat="0.69343 -0.720524 -2.92114e-05 0" type="cylinder" />
                        <geom conaffinity="0" size="0.0664305" pos="0 -0.00044 0.018066" quat="0.69343 -0.720524 -2.92114e-05 0" />
                        <geom conaffinity="0" size="0.0664305" pos="-8e-06 0.192169 0.010683" quat="0.69343 -0.720524 -2.92114e-05 0" />
                        <body name="ankle1_3" pos="0 0.2 0.10015" quat="0 1 0 0">
                            <inertial pos="0.000123601 -0.0627471 -0.00490685" quat="0.746546 0.647602 -0.0996407 0.115551" mass="1.40234" diaginertia="0.00499928 0.00492895 0.00169743" />
                            <joint name="ankle_pitch_3" pos="0 0 0" axis="0 0 -1" limited="true" range="-2.4696 2.4464" />
                            <geom conaffinity="0" size="0.0792379 0.0246282" pos="-3.39946e-05 -0.0238356 -1.2084e-05" quat="0.705951 0.70826 0.000349485 0" type="cylinder" />
                            <geom conaffinity="0" size="0.0792379" pos="-4.6e-05 0.000792 6.8e-05" quat="0.705951 0.70826 0.000349485 0" />
                            <geom conaffinity="0" size="0.0792379" pos="-2.2e-05 -0.048464 -9.3e-05" quat="0.705951 0.70826 0.000349485 0" />
                            <body name="ankle2_3" pos="0 -0.139 -0.00085" quat="0.707107 -0.707107 0 0">
                                <inertial pos="0.00184967 -0.000513224 -0.0673092" quat="0.999198 0.0156728 0.0368308 -0.00100998" mass="1.76567" diaginertia="0.00741457 0.00544457 0.00428742" />
                                <joint name="ankle_yaw_3" pos="0 0 0" axis="0 0 -1" limited="true" range="-2.5606 2.5454" />
                                <geom conaffinity="0" size="0.0813545 0.0368513" pos="-1.17781e-05 -0.00182701 -0.0652808" quat="0.00125264 0.995362 0.0961939 0" type="cylinder" />
                                <geom conaffinity="0" size="0.0813545" pos="-2.1e-05 -0.001735 -0.02843" quat="0.00125264 0.995362 0.0961939 0" />
                                <geom conaffinity="0" size="0.0813545" pos="-3e-06 -0.001919 -0.102132" quat="0.00125264 0.995362 0.0961939 0" />
                                <body name="wheel_3" pos="0 0 -0.09835" quat="0.707107 0.707107 0 0">
                                    <inertial pos="0 0 -0.00311559" quat="0 0.707107 0 0.707107" mass="1.11164" diaginertia="0.00418172 0.00281756 0.00281741" />
                                    <joint name="j_wheel_3" pos="0 0 0" axis="0 0 -1" />
                                    <geom conaffinity="0" size="0.078 0.055" type="cylinder" rgba="0.4 0.4 0.4 1" />
                                    <geom conaffinity="0" size="0.078" pos="0 0 -0.055" rgba="0.4 0.4 0.4 1" />
                                    <geom conaffinity="0" size="0.078" pos="0 0 0.055" rgba="0.4 0.4 0.4 1" />
                                </body>
                            </body>
                        </body>
                    </body>
                </body>
            </body>
            <body name="hip1_4" pos="-0.25 -0.125 -0.0566">
                <inertial pos="0.000359586 -0.0333388 -0.0591903" quat="0.685529 0.712917 0.104718 -0.104088" mass="2.33492" diaginertia="0.00685516 0.00668482 0.00262008" />
                <joint name="hip_yaw_4" pos="0 0 0" axis="0 0 -1" limited="true" range="-2.03 2.51" />
                <geom conaffinity="0" size="0.0747223 0.0153477" pos="0.000123454 0.0119497 -0.0631367" quat="0.802262 0.596933 0.00689249 0" type="cylinder" />
                <geom conaffinity="0" size="0.0747223" pos="-4.6e-05 0.02665 -0.067545" quat="0.802262 0.596933 0.00689249 0" />
                <geom conaffinity="0" size="0.0747223" pos="0.000293 -0.00275 -0.058728" quat="0.802262 0.596933 0.00689249 0" />
                <body name="hip2_4" pos="0 -0.1146 -0.0625" quat="0.707107 0.707107 0 0">
                    <inertial pos="-4.6286e-06 -0.221402 -0.0331668" quat="0.653967 0.756514 -0.00285355 0.00236922" mass="3.45721" diaginertia="0.0504699 0.0490878 0.00730749" />
                    <joint name="hip_pitch_4" pos="0 0 0" axis="0 0 1" limited="true" range="-2.0326 2.0524" />
                    <geom conaffinity="0" size="0.0808941 0.14599" pos="1.10697e-06 -0.13974 -0.0170087" quat="0.714186 -0.699955 -5.07264e-06 0" type="cylinder" />
                    <geom conaffinity="0" size="0.0808941" pos="2e-06 -0.285701 -0.019947" quat="0.714186 -0.699955 -5.07264e-06 0" />
                    <geom conaffinity="0" size="0.0808941" pos="0 0.00622 -0.014071" quat="0.714186 -0.699955 -5.07264e-06 0" />
                    <body name="knee_4" pos="0 -0.3 -0.1182" quat="0 1 0 0">
                        <inertial pos="0.000120634 0.146207 -0.0297407" quat="0.765124 0.630451 -0.0825892 0.101469" mass="2.11993" diaginertia="0.0184356 0.0182996 0.00425349" />
                        <joint name="knee_pitch_4" pos="0 0 0" axis="0 0 1" limited="true" range="-2.4176 2.3884" />
                        <geom conaffinity="0" size="0.0664305 0.0963751" pos="-4.07652e-06 0.0958646 -0.0143745" quat="0.720524 -0.69343 -2.8113e-05 0" type="cylinder" />
                        <geom conaffinity="0" size="0.0664305" pos="0 -0.00044 -0.018066" quat="0.720524 -0.69343 -2.8113e-05 0" />
                        <geom conaffinity="0" size="0.0664305" pos="-8e-06 0.192169 -0.010683" quat="0.720524 -0.69343 -2.8113e-05 0" />
                        <body name="ankle1_4" pos="0 0.2 -0.10015" quat="0 1 0 0">
                            <inertial pos="0.000123601 -0.0627471 0.00490685" quat="0.647602 0.746546 0.115551 -0.0996407" mass="1.40234" diaginertia="0.00499928 0.00492895 0.00169743" />
                            <joint name="ankle_pitch_4" pos="0 0 0" axis="0 0 1" limited="true" range="-2.3426 2.3934" />
                            <geom conaffinity="0" size="0.0781037 0.023942" pos="2.26075e-07 -0.0207647 0.000108892" quat="0.699852 -0.714288 0.000212448 0" type="cylinder" />
                            <geom conaffinity="0" size="0.0781037" pos="-7e-06 -0.044702 0.000598" quat="0.699852 -0.714288 0.000212448 0" />
                            <geom conaffinity="0" size="0.0781037" pos="7e-06 0.003172 -0.00038" quat="0.699852 -0.714288 0.000212448 0" />
                            <body name="ankle2_4" pos="0 -0.139 0.00085" quat="0.707107 -0.707107 0 0">
                                <inertial pos="0.00184967 0.000513224 -0.0673092" quat="0.999198 -0.0156728 0.0368308 0.00100998" mass="1.76567" diaginertia="0.00741457 0.00544457 0.00428742" />
                                <joint name="ankle_yaw_4" pos="0 0 0" axis="0 0 -1" limited="true" range="-2.6046 2.5514" />
                                <geom conaffinity="0" size="0.0813545 0.0368513" pos="-1.17781e-05 0.00182701 -0.0652808" quat="0.00125264 -0.995362 0.0961939 0" type="cylinder" />
                                <geom conaffinity="0" size="0.0813545" pos="-2.1e-05 0.001735 -0.02843" quat="0.00125264 -0.995362 0.0961939 0" />
                                <geom conaffinity="0" size="0.0813545" pos="-3e-06 0.001919 -0.102132" quat="0.00125264 -0.995362 0.0961939 0" />
                                <body name="wheel_4" pos="0 0 -0.09835" quat="0.707107 0.707107 0 0">
                                    <inertial pos="0 0 0.00311559" quat="0 0.707107 0 0.707107" mass="1.11164" diaginertia="0.00418172 0.00281756 0.00281741" />
                                    <joint name="j_wheel_4" pos="0 0 0" axis="0 0 1" />
                                    <geom conaffinity="0" size="0.078 0.055" type="cylinder" rgba="0.4 0.4 0.4 1" />
                                    <geom conaffinity="0" size="0.078" pos="0 0 -0.055" rgba="0.4 0.4 0.4 1" />
                                    <geom conaffinity="0" size="0.078" pos="0 0 0.055" rgba="0.4 0.4 0.4 1" />
                                </body>
                            </body>
                        </body>
                    </body>
                </body>
            </body>
        </body>
    </worldbody>
</mujoco>
