<?xml version="1.0"?>
<robot xmlns:xacro="http://ros.org/wiki/xacro" name="pholus">

<!-- ************ MODEL CONFIGURATION ************ -->
<xacro:include filename="$(find pholus_urdf)/urdf/pholus_config.urdf.xacro" />

<!-- ************ Pholus plain model ************ -->
<xacro:include filename="$(find pholus_urdf)/urdf/pholus_base.urdf.xacro"/>

<!-- ************ Control frames ************ -->
<xacro:include filename="$(find pholus_urdf)/urdf/control_frames.urdf.xacro"/>

<xacro:if value="${ADD_FLOATING_BASE}">
<link name="world"/>

  <joint name="reference" type="floating">
    <parent link="world"/>
    <child link="base_link"/>
</joint>
</xacro:if>
<xacro:unless value="${ADD_FLOATING_BASE}">
<link name="world"/>

  <joint name="reference" type="fixed">
    <parent link="world"/>
    <child link="base_link"/>
</joint>
</xacro:unless>

</robot>
