<?xml version="1.0" ?>
<!-- =================================================================================== -->
<!-- |    This document was autogenerated by xacro from /home/damigas/isaac_gym_ws/IsaacGymEnvs/assets/urdf/centauro_description/iit-centauro-ros-pkg/centauro_urdf/urdf/centauro.urdf.xacro | -->
<!-- |    EDITING THIS FILE BY HAND IS NOT RECOMMENDED                                 | -->
<!-- =================================================================================== -->
<robot name="centauro">
  <!-- none, ball, dagana_fixed, dagana -->
  <!-- 
  ROS urdf definition of the CENTAURO humanoid robot by Istituto Italiano di Tecnologia
  
  Author: Enrico Mingo Hoffman
-->
  <!-- scaling facto for available peack torque link side, from 0 to 1 -->
  <material name="black">
    <color rgba="0.4 0.4 0.4 1"/>
  </material>
  <material name="dark">
    <color rgba="0.1 0.1 0.1 1"/>
  </material>
  <material name="dark_grey">
    <color rgba="0.2 0.2 0.2 1"/>
  </material>
  <!-- Note: the "23" suffix denotes the new bigger-size wheel -->
  <!-- ??? -->
  <!-- ??? -->
  <!-- Origin -->
  <!-- <xacro:property name="hip_yaw_lower" value="${[-2.827,-2.583, -2.583 ,-2.827]}"/>
<xacro:property name="hip_yaw_upper" value="${[ 2.583, 2.827,  2.827 , 2.583]}"/> -->
   
  <!-- torso links -->
  <link name="torso_2">
    <inertial>
      <origin xyz="-0.019497794 0.0045317835 0.13768283"/>
      <mass value="12.553731"/>
      <inertia ixx="0.063643392" ixy="8.939e-05" ixz="-0.00086873" iyy="0.02680235" iyz="-4.657e-05" izz="0.04743015"/>
    </inertial>
    <visual>
      <origin rpy="0.0 0.0 0.0" xyz="0.0 0 0.0"/>
      <geometry>
        <mesh filename="/home/damigas/isaac_gym_ws/IsaacGymEnvs/assets/urdf/centauro_description/iit-centauro-ros-pkg/centauro_urdf/meshes/link1_no_head.stl" scale="0.001 0.001 0.001"/>
      </geometry>
    </visual>
    <collision>
      <origin rpy="0.0 0.0 0.0" xyz="0.0 0 0.0"/>
      <geometry>
        <mesh filename="/home/damigas/isaac_gym_ws/IsaacGymEnvs/assets/urdf/centauro_description/iit-centauro-ros-pkg/centauro_urdf/meshes/simple/link1_no_head.stl" scale="0.001 0.001 0.001"/>
      </geometry>
    </collision>
  </link>
  <!-- /torso links -->
   
   
   
   
   
  <!-- LINKS -->
  <!-- shoulder yaw-roll-->
  <link name="arm2_1">
    <inertial>
      <origin xyz="-0.0074457212 -0.03410796 0.00010978102"/>
      <mass value="1.9628675"/>
      <inertia ixx="0.0053547717" ixy="-0.00036428926" ixz="1.5089568e-05" iyy="0.0033923328" iyz="-5.5692312e-05" izz="0.0068921413"/>
    </inertial>
    <visual>
      <origin rpy="0.0 0.0 0.0" xyz="0.0 0.0 0.0"/>
      <geometry>
        <mesh filename="/home/damigas/isaac_gym_ws/IsaacGymEnvs/assets/urdf/centauro_description/iit-centauro-ros-pkg/centauro_urdf/meshes/ShoulderPitch.STL" scale="0.001 0.001 0.001"/>
      </geometry>
      <material name="dark_grey"/>
    </visual>
    <collision>
      <origin rpy="0.0 0.0 0.0" xyz="0.0 0.0 0.0"/>
      <geometry>
        <mesh filename="/home/damigas/isaac_gym_ws/IsaacGymEnvs/assets/urdf/centauro_description/iit-centauro-ros-pkg/centauro_urdf/meshes/simple/ShoulderPitch.STL" scale="0.001 0.001 0.001"/>
      </geometry>
    </collision>
  </link>
  <!-- shoulder yaw-roll-->
  <!-- shoulder roll-pitch-->
  <link name="arm2_2">
    <inertial>
      <origin xyz="0.058142302 -5.7450803e-05 -0.077477683"/>
      <mass value="1.8595811"/>
      <inertia ixx="0.013776643" ixy="-3.7788675e-05" ixz="0.0037690171" iyy="0.015677464" iyz="9.4893549e-06" izz="0.0046317657"/>
    </inertial>
    <visual>
      <origin rpy="0.0 0.0 0.0" xyz="0.0 0.0 0.0"/>
      <geometry>
        <mesh filename="/home/damigas/isaac_gym_ws/IsaacGymEnvs/assets/urdf/centauro_description/iit-centauro-ros-pkg/centauro_urdf/meshes/ShoulderRoll.STL" scale="0.001 0.001 0.001"/>
      </geometry>
    </visual>
    <collision>
      <origin rpy="0.0 0.0 0.0" xyz="0.0 0.0 0.0"/>
      <geometry>
        <mesh filename="/home/damigas/isaac_gym_ws/IsaacGymEnvs/assets/urdf/centauro_description/iit-centauro-ros-pkg/centauro_urdf/meshes/simple/ShoulderRoll.STL" scale="0.001 0.001 0.001"/>
      </geometry>
    </collision>
  </link>
  <!-- shoulder roll-pitch-->
  <!-- shoulder-elbow -->
  <link name="arm2_3">
    <inertial>
      <origin xyz="0.014625194 -0.0008172672 -0.028333545"/>
      <mass value="1.6678109"/>
      <inertia ixx="0.0064480435" ixy="0.00015639093" ixz="0.0012205359" iyy="0.0073372077" iyz="-8.9941532e-05" izz="0.0036738448"/>
    </inertial>
    <visual>
      <origin rpy="0.0 0.0 0.0" xyz="0.0 0.0 0.0"/>
      <geometry>
        <mesh filename="/home/damigas/isaac_gym_ws/IsaacGymEnvs/assets/urdf/centauro_description/iit-centauro-ros-pkg/centauro_urdf/meshes/ShoulderYaw.STL" scale="0.001 0.001 0.001"/>
      </geometry>
      <material name="dark_grey"/>
    </visual>
    <collision>
      <origin rpy="0.0 0.0 0.0" xyz="0.0 0.0 0.0"/>
      <geometry>
        <mesh filename="/home/damigas/isaac_gym_ws/IsaacGymEnvs/assets/urdf/centauro_description/iit-centauro-ros-pkg/centauro_urdf/meshes/simple/ShoulderYaw.STL" scale="0.001 0.001 0.001"/>
      </geometry>
    </collision>
  </link>
  <!-- /shoulder-elbow -->
  <!-- elbow yaw-pitch -->
  <link name="arm2_4">
    <inertial>
      <origin xyz="-0.0076833067 0.040302205 -0.043492779"/>
      <mass value="1.3157289"/>
      <inertia ixx="0.004330394" ixy="0.00011737391" ixz="-0.00041923199" iyy="0.0038539919" iyz="0.00079573038" izz="0.0017594689"/>
    </inertial>
    <visual>
      <origin rpy="0.0 0.0 0.0" xyz="0.0 0.0 0.0"/>
      <geometry>
        <mesh filename="/home/damigas/isaac_gym_ws/IsaacGymEnvs/assets/urdf/centauro_description/iit-centauro-ros-pkg/centauro_urdf/meshes/Elbow.STL" scale="0.001 0.001 0.001"/>
      </geometry>
    </visual>
    <collision>
      <origin rpy="0.0 0.0 0.0" xyz="0.0 0.0 0.0"/>
      <geometry>
        <mesh filename="/home/damigas/isaac_gym_ws/IsaacGymEnvs/assets/urdf/centauro_description/iit-centauro-ros-pkg/centauro_urdf/meshes/simple/Elbow.STL" scale="0.001 0.001 0.001"/>
      </geometry>
    </collision>
  </link>
  <!-- /elbow yaw-pitch -->
  <!-- elbow-wrist -->
  <link name="arm2_5">
    <inertial>
      <origin xyz="-0.00011079615 -0.011590836 -0.07816026"/>
      <mass value="1.4908547"/>
      <inertia ixx="0.0085692128" ixy="-1.7856252e-05" ixz="1.9379365e-05" iyy="0.0077454159" iyz="0.00032860094" izz="0.0027441921"/>
    </inertial>
    <visual>
      <origin rpy="0.0 0.0 0.0" xyz="0.0 0.0 0.0"/>
      <geometry>
        <mesh filename="/home/damigas/isaac_gym_ws/IsaacGymEnvs/assets/urdf/centauro_description/iit-centauro-ros-pkg/centauro_urdf/meshes/Forearm.STL" scale="0.001 0.001 0.001"/>
      </geometry>
      <material name="dark_grey"/>
    </visual>
    <collision>
      <origin rpy="0.0 0.0 0.0" xyz="0.0 0.0 0.0"/>
      <geometry>
        <mesh filename="/home/damigas/isaac_gym_ws/IsaacGymEnvs/assets/urdf/centauro_description/iit-centauro-ros-pkg/centauro_urdf/meshes/simple/Forearm.STL" scale="0.001 0.001 0.001"/>
      </geometry>
    </collision>
  </link>
  <!-- /elbow-wrist -->
  <!-- wrist yaw-pitch -->
  <link name="arm2_6">
    <inertial>
      <origin xyz="-4.6502396e-06 0.038014094 -0.069926878"/>
      <mass value="1.1263612"/>
      <inertia ixx="0.0051871784" ixy="-2.724437e-05" ixz="2.2833496e-06" iyy="0.0048037789" iyz="0.00072165653" izz="0.0012771388"/>
    </inertial>
    <visual>
      <origin rpy="0.0 0.0 0.0" xyz="0.0 0.0 0.0"/>
      <geometry>
        <mesh filename="/home/damigas/isaac_gym_ws/IsaacGymEnvs/assets/urdf/centauro_description/iit-centauro-ros-pkg/centauro_urdf/meshes/wrist_pitch_right.stl" scale="0.001 0.001 0.001"/>
      </geometry>
    </visual>
    <collision>
      <origin rpy="0.0 0.0 0.0" xyz="0.0 0.0 0.0"/>
      <geometry>
        <mesh filename="/home/damigas/isaac_gym_ws/IsaacGymEnvs/assets/urdf/centauro_description/iit-centauro-ros-pkg/centauro_urdf/meshes/simple/wrist_pitch_right.stl" scale="0.001 0.001 0.001"/>
      </geometry>
    </collision>
  </link>
  <!-- /wrist yaw-pitch -->
  <!-- <link name="arm${arm_num}_7">
      <inertial>
         <origin xyz="${Wrist_3_x} ${rot*Wrist_3_y} ${Wrist_3_z}"/>
         <mass value="${Wrist_3_mass}"/>
         <inertia ixx="${Wrist_3_xx}" ixy="${rot*Wrist_3_xy}" ixz="${Wrist_3_xz}" iyy="${Wrist_3_yy}" iyz="${rot*Wrist_3_yz}" izz="${Wrist_3_zz}"/>
      </inertial>

      <visual>
         <origin xyz="0.0 0.0 0.0"  rpy="0.0 0.0 0.0"/>
   <geometry>
      <mesh filename="/home/damigas/isaac_gym_ws/IsaacGymEnvs/assets/urdf/centauro_description/iit-centauro-ros-pkg/centauro_urdf/meshes/ForearmYaw.STL" scale="0.001 ${-rot*0.001} 0.001" />
   </geometry>
         <material name="dark_grey"/>
      </visual>

      <collision>
         <origin xyz="0.0 0.0 0.0"  rpy="0.0 0.0 0.0"/>
   <geometry>
      <mesh filename="/home/damigas/isaac_gym_ws/IsaacGymEnvs/assets/urdf/centauro_description/iit-centauro-ros-pkg/centauro_urdf/meshes/simple/ForearmYaw.STL" scale="0.001 ${-rot*0.001} 0.001" />
   </geometry>
      </collision>
   </link> -->
  <!-- /LINKS -->
  <!-- JOINTS -->
  <!-- shoulder yaw -->
  <joint name="j_arm2_1" type="revolute">
    <parent link="torso_2"/>
    <child link="arm2_1"/>
    <origin rpy="-0.174533 0.0 0.5235988" xyz="0.0457475 -0.169137 0.116626"/>
    <axis xyz="0 1 0"/>
    <limit effort="147.0" lower="-3.3458" upper="1.6012" velocity="3.86"/>
  </joint>
  <!-- /shoulder yaw -->
  <!-- shoulder roll -->
  <joint name="j_arm2_2" type="revolute">
    <parent link="arm2_1"/>
    <child link="arm2_2"/>
    <origin rpy="0.1745327 0.0 0.0" xyz="-0.09015 -0.062 0.0"/>
    <axis xyz="1 0 0"/>
    <limit effort="147.0" lower="-3.4258" upper="-0.0138" velocity="3.86"/>
  </joint>
  <!-- /shoulder roll -->
  <!-- shoulder pitch-->
  <joint name="j_arm2_3" type="revolute">
    <parent link="arm2_2"/>
    <child link="arm2_3"/>
    <origin xyz="0.09015 0.0 -0.21815"/>
    <axis xyz="0 0 1"/>
    <limit effort="147.0" lower="-2.5614" upper="2.5606" velocity="6.06"/>
  </joint>
  <!-- /shoulder pitch -->
  <!-- elbow yaw -->
  <joint name="j_arm2_4" type="revolute">
    <parent link="arm2_3"/>
    <child link="arm2_4"/>
    <origin xyz="0.045 -0.05515 -0.074"/>
    <axis xyz="0 1 0"/>
    <limit effort="147.0" lower="-2.4794" upper="0.2886" velocity="6.06"/>
  </joint>
  <!-- /elbow yaw -->
  <!-- elbow pitch-->
  <joint name="j_arm2_5" type="revolute">
    <parent link="arm2_4"/>
    <child link="arm2_5"/>
    <origin xyz="-0.015 0.05515 -0.095"/>
    <axis xyz="0 0 1"/>
    <limit effort="55.0" lower="-2.5394" upper="2.5546" velocity="11.72"/>
  </joint>
  <!-- /elbow pitch-->
  <!-- wrist yaw-->
  <joint name="j_arm2_6" type="revolute">
    <parent link="arm2_5"/>
    <child link="arm2_6"/>
    <origin xyz="0.0 -0.049 -0.156"/>
    <axis xyz="0 1 0"/>
    <limit effort="55.0" lower="-1.5154" upper="1.5156" velocity="11.72"/>
  </joint>
  <!-- /wrist yaw-->
  <!-- wrist pitch-->
  <!-- <joint name="j_arm${arm_num}_7" type="fixed">
      <parent link="arm${arm_num}_6"/>
      <child link="arm${arm_num}_7"/>
      <origin xyz="${Wrist_3_Ox} ${rot*Wrist_3_Oy} ${Wrist_3_Oz}"/>
      <axis xyz="0 0 1"/>
      <limit lower="${j_arm_7_lower[arm_num-1]}" upper="${j_arm_7_upper[arm_num-1]}" effort="${j_arm_7_torque[arm_num-1]}" velocity="${j_arm_7_velocity[arm_num-1]}"/>
   </joint> -->
  <!-- wrist pitch-->
  <!-- force-troque sensor -->
  <!-- end-effector -->
  <!-- wrist pitch-->
  <!-- <joint name="j_ft_${arm_num}" type="fixed">
      <parent link="arm${arm_num}_7"/>
      <child link="ft_arm${arm_num}"/>
      <origin xyz="${Ft_arm_Ox} ${Ft_arm_Oy} ${Ft_arm_Oz}" rpy="${Ft_arm_roll} ${Ft_arm_pitch} ${Ft_arm_yaw}" />
      <axis xyz="0 0 1"/>
      <limit lower="0.0" upper="0.0" effort="0" velocity="0"/>
   </joint> -->
  <!-- wrist pitch-->
  <!-- <link name="ft_arm${arm_num}">
      <inertial>
         <origin xyz="${Ft_arm_x} ${rot*Ft_arm_y} ${Ft_arm_z}"/>
         <mass value="${Ft_arm_mass}"/>
         <inertia ixx="${Ft_arm_xx}" ixy="${rot*Ft_arm_xy}" ixz="${Ft_arm_xz}" iyy="${Ft_arm_yy}" iyz="${rot*Ft_arm_yz}" izz="${Ft_arm_zz}"/>
      </inertial> -->
  <!--visual>
         <origin xyz="0.0 0.0 0.0"  rpy="${PI} 0.0 0.0"/>
   <geometry>
      <mesh filename="/home/damigas/isaac_gym_ws/IsaacGymEnvs/assets/urdf/centauro_description/iit-centauro-ros-pkg/centauro_urdf/meshes/Wrist.STL" scale="0.001 ${-rot*0.001} 0.001" />
   </geometry>
      </visual-->
  <!--collision>
         <origin xyz="0.0 0.0 0.0"  rpy="${PI} 0.0 0.0"/>
   <geometry>
      <mesh filename="/home/damigas/isaac_gym_ws/IsaacGymEnvs/assets/urdf/centauro_description/iit-centauro-ros-pkg/centauro_urdf/meshes/simple/Wrist.STL" scale="0.001 ${-rot*0.001} 0.001" />
   </geometry>
      </collision-->
  <!-- </link> -->
   
   
  <joint name="dagana_2_mount_joint" type="fixed">
    <origin rpy="0. 3.14159265359 0" xyz="0. 0.05 -0.08"/>
    <parent link="arm2_6"/>
    <child link="dagana_2_top_link"/>
  </joint>
  <link name="dagana_2_top_link">
    <inertial>
      <origin rpy="0 0 0" xyz="-0.0063562154 -0.0060265532000000005  0.060068288000000004"/>
      <mass value="1.7432400"/>
      <inertia ixx="0.0050510328" ixy="-0.00025264216" ixz="-0.00012103013" iyy="0.0047944612" iyz="-0.00073917704" izz="0.0031156997"/>
    </inertial>
    <visual>
      <origin rpy="0 0 0" xyz="0 0 0"/>
      <geometry>
        <mesh filename="/home/damigas/isaac_gym_ws/IsaacGymEnvs/assets/urdf/centauro_description/iit-dagana-ros-pkg/dagana_urdf/meshes/dg0001-simplified.stl" scale="0.001 0.001 0.001"/>
      </geometry>
      <material name="dark_grey"/>
    </visual>
    <collision>
      <origin rpy="0 0 0" xyz="0 0 0"/>
      <geometry>
        <mesh filename="/home/damigas/isaac_gym_ws/IsaacGymEnvs/assets/urdf/centauro_description/iit-dagana-ros-pkg/dagana_urdf/meshes/dg0001-ch.stl" scale="0.001 0.001 0.001"/>
      </geometry>
      <material name="dark_grey"/>
    </collision>
  </link>
  <joint name="dagana_2_claw_joint" type="revolute">
    <origin rpy="1.57079632679 0 3.14159265359" xyz="0.0 -0.028 0.05025"/>
    <parent link="dagana_2_top_link"/>
    <child link="dagana_2_bottom_link"/>
    <axis xyz="-1 0 0"/>
    <limit effort="1000" lower="0" upper="1" velocity="2.0"/>
  </joint>
  <link name="dagana_2_bottom_link">
    <inertial>
      <origin rpy="0 0 0" xyz="0 0.069644767 0"/>
      <mass value="4.6117745e-01"/>
      <inertia ixx="0.0014726990999999999" ixy="7.134683e-05" ixz="2.529065e-06" iyy="0.0009385556899999999" iyz="-0.000264452" izz="0.0019472731"/>
    </inertial>
    <visual>
      <origin rpy="0 0 0" xyz="0 0 0"/>
      <geometry>
        <mesh filename="/home/damigas/isaac_gym_ws/IsaacGymEnvs/assets/urdf/centauro_description/iit-dagana-ros-pkg/dagana_urdf/meshes/dg0002.stl" scale="0.001 0.001 0.001"/>
      </geometry>
      <material name="dark_grey"/>
    </visual>
    <collision>
      <origin rpy="0 0 0" xyz="0 0 0"/>
      <geometry>
        <mesh filename="/home/damigas/isaac_gym_ws/IsaacGymEnvs/assets/urdf/centauro_description/iit-dagana-ros-pkg/dagana_urdf/meshes/dg0002-ch.stl" scale="0.001 0.001 0.001"/>
      </geometry>
      <material name="dark_grey"/>
    </collision>
  </link>
  <!-- Manually put to have a transform in a "good" grasping spot-->
  <joint name="dagana_2_tcp_joint" type="fixed">
    <origin rpy="0 0 0" xyz="0 -0.05 0.15"/>
    <parent link="dagana_2_top_link"/>
    <child link="dagana_2_tcp"/>
  </joint>
  <link name="dagana_2_tcp"/>
  <!-- add armX_8 link for compliance with srdf file -->
  <joint name="j_dagana_2_final" type="fixed">
    <parent link="dagana_2_bottom_link"/>
    <child link="arm2_8"/>
  </joint>
  <link name="arm2_8">
    <inertial>
      <mass value="0"/>
      <inertia ixx="0" ixy="0" ixz="0" iyy="0" iyz="0" izz="0"/>
    </inertial>
  </link>
  
  <!-- Fake links at tips of dagana /home/dgasperini/Desktop/isaac_arm1_centauro.urdf -->
  <joint name="j_dagana_top_tip" type="fixed">
    <origin rpy="0 0 0" xyz="0 0.005 0.222"/>
    <parent link="dagana_2_top_link"/>
    <child link="dagana_top_tip"/>
  </joint>
  <link name="dagana_top_tip"/>
  
  <joint name="j_dagana_bottom_tip" type="fixed">
    <origin rpy="0 0 0" xyz="0 0.17175 0.03241"/>
    <parent link="dagana_2_bottom_link"/>
    <child link="dagana_bottom_tip"/>
  </joint>
  <link name="dagana_bottom_tip"/>
   
</robot>
