<?xml version="1.0"?>
<robot xmlns:xacro="http://ros.org/wiki/xacro">

<!-- LINKS -->
<!-- TODO: FINISH IMPLEMENTATION WITH CORRECT NUMBERS -->
<link name="neck_1"/>
<link name="neck_2"/>
<link name="neck_3"/>

<!--JOINTS -->
<joint name="neck_yaw" type="revolute">
    <parent link="torso_2"/>
    <origin xyz="0.0 0.0 0.2795"/>
    <child link="neck_1"/>
    <axis xyz="0 0 1"/>
    <limit effort="35" lower="-0.78539816" upper="0.78539816" velocity="5.7"/>
    <dynamics friction="10.0"/>
</joint>

<joint name="neck_pitch" type="revolute">
    <parent link="neck_1"/>
    <origin xyz="0.054 0.0596 -0.0124975"/>
    <child link="neck_2"/>
    <axis xyz="0 1 0"/>
    <limit effort="35" lower="-0.34906585" upper="0.78539816" velocity="5.7"/>
    <dynamics friction="10.0"/>
</joint>

<joint name="neck_velodyne" type="continuous">
    <parent link="torso_2"/>
    <origin xyz="0.055 0.0 0.473262" rpy="0 0 -1.828"/>
    <!--origin xyz="0.055 0.0 0.473262" rpy="0 0 -1.311481"/-->
    <child link="neck_3"/>
    <axis xyz="0 0 1"/>
    <limit effort="35" velocity="5.7"/>
    <dynamics damping="0.2" friction="10.0"/>
</joint>
</robot>
