<?xml version="1.0"?>
<robot xmlns:xacro="http://ros.org/wiki/xacro">

  <!-- LINKS -->
  <link name="neck_1">
    <inertial>
      <origin xyz="0 0 0"/>
      <mass value="0.33878686"/>
      <!-- MASS/INERTIA TO DO -->
      <inertia ixx="0.0003718568" ixy="-9.42983e-05" ixz="-2.80644e-05" iyy="0.0001886879" iyz="-1.54534e-05" izz="0.0005023443"/>
    </inertial>
    <visual>
      <origin rpy="0.0 0.0 0.0" xyz="0.0 0 0.0"/>
      <geometry>
        <mesh filename="package://centauro_urdf/meshes/head-base_mesh.stl" scale="0.001 0.001 0.001"/>
      </geometry>
    </visual>
    <collision>
      <origin rpy="0.0 0.0 0.0" xyz="0.0 0 0.0"/>
      <geometry>
        <mesh filename="package://centauro_urdf/meshes/simple/head-base_mesh.stl" scale="0.001 0.001 0.001"/>
      </geometry>
    </collision>
  </link>

  <link name="velodyne_motor">
    <inertial>
      <origin xyz="0 0 0"/>
      <mass value="0.33878686"/>
      <!-- MASS/INERTIA TO DO -->
      <inertia ixx="0.0003718568" ixy="-9.42983e-05" ixz="-2.80644e-05" iyy="0.0001886879" iyz="-1.54534e-05" izz="0.0005023443"/>
    </inertial>
    <visual>
      <origin rpy="0.0 0.0 0.0" xyz="0.0 0 0.0"/>
      <geometry>
        <mesh filename="package://centauro_urdf/meshes/lidar_mesh.stl" scale="0.001 0.001 0.001"/>
      </geometry>
    </visual>
    <collision>
      <origin rpy="0.0 0.0 0.0" xyz="0.0 0 0.0"/>
      <geometry>
        <mesh filename="package://centauro_urdf/meshes/simple/lidar_mesh.stl" scale="0.001 0.001 0.001"/>
      </geometry>
    </collision>
  </link>

  <link name="d435_head_motor">
    <inertial>
      <origin xyz="0 0 0"/>
      <mass value="0.33878686"/>
      <!-- MASS/INERTIA TO DO -->
      <inertia ixx="0.0003718568" ixy="-9.42983e-05" ixz="-2.80644e-05" iyy="0.0001886879" iyz="-1.54534e-05" izz="0.0005023443"/>
    </inertial>
    <visual>
      <origin rpy="0.0 0.0 0.0" xyz="0.0 0 0.0"/>
      <geometry>
        <mesh filename="package://centauro_urdf/meshes/neck-pitch_mesh.stl" scale="0.001 0.001 0.001"/>
      </geometry>
    </visual>
    <collision>
      <origin rpy="0.0 0.0 0.0" xyz="0.0 0 0.0"/>
      <geometry>
        <mesh filename="package://centauro_urdf/meshes/simple/neck-pitch_mesh.stl" scale="0.001 0.001 0.001"/>
      </geometry>
    </collision>
  </link>

  <!--JOINTS -->
  <joint name="neck_base" type="fixed">
    <parent link="torso_2"/>
    <origin xyz="0.0030637045 0.0061607221 0.158" rpy="0 0 0"/>
    <child link="neck_1"/>
    <axis xyz="0 0 1"/>
  </joint>

  <joint name="velodyne_joint" type="revolute">
    <parent link="neck_1"/>
    <origin xyz="0.0822724 0 0.242" rpy="0 0 0"/>
    <child link="velodyne_motor"/>
    <axis xyz="0 -1 0"/>
    <limit effort="35" lower="-1.1" upper="1.1" velocity="5.7"/>
    <dynamics friction="10.0"/>
  </joint>

  <joint name="d435_head_joint" type="revolute">
    <parent link="neck_1"/>
    <origin xyz="0.06 0 0.1375" rpy="0 0 0"/>
    <child link="d435_head_motor"/>
    <axis xyz="0 -1 0"/>
    <limit effort="35" lower="-1.1" upper="1.1" velocity="5.7"/>
    <dynamics friction="10.0"/>
  </joint>

  <xacro:if value="${ADD_D435I_HEAD}">

    <xacro:include filename="$(find realsense_gazebo_description)/urdf/_d435i.urdf.xacro" />

    <xacro:sensor_d435i parent="d435_head_motor" 
        name="D435_head_camera" 
        topics_ns="D435/D435_head_camera" 
        enable_pointCloud="true" 
        align_depth="true" 
        unite_imu_method="false" 
        visualize="false" 
        accel_fps="300" 
        gyro_fps="300" 
        depth_width="1280" 
        depth_height="720" 
        depth_fps="90" 
        infra_width="1280" 
        infra_height="720" 
        infra_fps="90" 
        color_width="1280" 
        color_height="720" 
        color_fps="30">

      <origin xyz="0.03015 0 -0.0125" rpy="0 0 0"/>

    </xacro:sensor_d435i>
    
  </xacro:if>

  <xacro:if value="${ADD_VELODYNE}">
    <xacro:include filename="$(find velodyne_description)/urdf/VLP-16.urdf.xacro"/>
    <xacro:VLP-16 parent="velodyne_motor" name="velodyne_calib" topic="/velodyne_points" hz="10" samples="440">
        <origin xyz="0 0 0" rpy="0 0 0" />
    </xacro:VLP-16>
  </xacro:if>

</robot>