<?xml version="1.0"?>
<robot xmlns:xacro="http://ros.org/wiki/xacro">

<!-- LINKS -->
<link name="d435i_base_torso">
    <inertial>
      <origin xyz="0.048466918 -0.059852318 -0.0085314894"/>
      <mass value="0.78526942"/>
      <inertia ixx="0.0004682345" ixy="-1.05438e-05" ixz="7.24398e-05" iyy="0.0002635246" iyz="1.6904e-06" izz="0.0003763351"/>
    </inertial>
    <visual>
      <origin rpy="0.0 0.0 0.0" xyz="0.0 0 0.0"/>
      <geometry>
        <mesh filename="package://centauro_urdf/meshes/lidar.stl" scale="0.0001 0.0001 0.0001"/>
      </geometry>
    </visual>
    <collision>
      <origin rpy="0.0 0.0 0.0" xyz="0.0 0 0.0"/>
      <geometry>
        <mesh filename="package://centauro_urdf/meshes/simple/lidar.stl" scale="0.0001 0.0001 0.0001"/>
      </geometry>
    </collision>
</link>

<joint name="intel_base_joint" type="continuous">
    <parent link="torso_2"/>
    <origin xyz="0 0 0" rpy="0 0 0"/>
    <child link="d435i_base_torso"/>
    <axis xyz="0 0 1"/>
    <limit effort="35" velocity="5.7"/>
    <dynamics damping="0.2" friction="10.0"/>
</joint>

</robot>
