<?xml version="1.0"?>
<robot xmlns:xacro="http://ros.org/wiki/xacro">

    <!-- macro arms -->
    <xacro:macro name="centauro_wheel23" params="leg_num mirror">

        <link name="ankle2_${leg_num}">
            <inertial>
                <origin xyz="${Ankle23_2_x} ${mirror*Ankle23_2_y} ${Ankle23_2_z}" />
                <mass value="${Ankle23_2_mass}" />  <!-- org: 3.5, foot un modeled-->
                <inertia ixx="${Ankle23_2_xx}" ixy="${mirror*Ankle23_2_xy}" ixz="${Ankle23_2_xz}"
                    iyy="${Ankle23_2_yy}" iyz="${mirror*Ankle23_2_yz}" izz="${Ankle23_2_zz}" />
            </inertial>

            <visual>
                <origin xyz="0.0 0.0 0.0" rpy="0.0 0.0 0.0" />
                <geometry>
                    <mesh filename="package://centauro_urdf/meshes/v2/mesh_ankle-yaw_wheel23.stl"
                        scale="0.001 ${mirror*0.001} 0.001" />
                </geometry>
                <material name="dark_grey" />
            </visual>

            <collision>
                <origin xyz="0.0 0.0 0.0" rpy="0.0 0.0 0.0" />
                <geometry>
                    <mesh
                        filename="package://centauro_urdf/meshes/v2/collision/mesh_ankle-yaw_wheel23.stl"
                        scale="0.001 ${mirror*0.001} 0.001" />
                </geometry>
            </collision>
        </link>

        <joint name="j_wheel_${leg_num}" type="continuous">
            <parent link="ankle2_${leg_num}" />
            <child link="wheel_${leg_num}" />
            <origin xyz="${Wheel23_Ox} ${mirror*Wheel23_Oy} ${Wheel23_Oz}"
                rpy="${Wheel23_roll} ${Wheel23_pitch} ${Wheel23_yaw}" />
            <axis xyz="0 0 ${mirror}" />
            <limit effort="${motor_C_effort}" velocity="${motor_C_velocity}" />  <!-- 23 Nm, 1
            rad/s-->
        </joint>

        <link name="wheel_${leg_num}">
            <inertial>
                <origin xyz="${Wheel23_x} ${Wheel23_y} ${mirror*Wheel23_z}" />
                <mass value="${Wheel23_mass}" />
                <inertia ixx="${Wheel23_xx}" ixy="${Wheel23_xy}" ixz="${mirror*Wheel23_xz}"
                    iyy="${Wheel23_yy}" iyz="${mirror*Wheel23_yz}" izz="${Wheel23_zz}" />
            </inertial>

            <visual>
                <origin xyz="0.0 0.0 0.0" rpy="0.0 0.0 0.0" />
                <geometry>
                    <mesh filename="package://centauro_urdf/meshes/v2/mesh_wheel23.stl"
                        scale="0.001 0.001 ${mirror*0.001}" />
                </geometry>
                <material name="black" />
            </visual>

            <collision>
                <origin xyz="0 0 0" rpy="0 0 0" />
                <geometry>
                    <mesh filename="package://centauro_urdf/meshes/v2/collision/mesh_wheel23.stl"
                        scale="0.001 0.001 ${mirror*0.001}" />
                </geometry>
                <material name="black" />
            </collision>
        </link>

    </xacro:macro>
    <!-- /macro arms -->

</robot>