<?xml version="1.0"?>
<robot xmlns:xacro="http://ros.org/wiki/xacro">

<!-- macro centauro_wheel -->
<xacro:macro name="centauro_wheel" params="leg_num mirror">

    <link name="ankle2_${leg_num}">
        <inertial>
        <origin xyz="${Ankle_2_x} ${mirror*Ankle_2_y} ${Ankle_2_z}"/>
        <mass value="${Ankle_2_mass}"/>  <!-- org 3.5, foot un modeled-->
        <inertia ixx="${Ankle_2_xx}" ixy="${mirror*Ankle_2_xy}" ixz="${Ankle_2_xz}" iyy="${Ankle_2_yy}" iyz="${mirror*Ankle_2_yz}" izz="${Ankle_2_zz}"/>
        </inertial>

        <visual>
        <origin xyz="0.0 0.0 0.0"  rpy="0.0 0.0 0.0"/>
        <geometry>
            <mesh filename="package://centauro_urdf/meshes/v2/ankle-yaw.stl" scale="0.001 ${mirror*0.001} 0.001" />
        </geometry>
        <material name="dark_grey"/>
        </visual>
        
        <collision>
        <origin xyz="0.0 0.0 0.0"  rpy="0.0 0.0 0.0"/>
        <geometry>
            <mesh filename="package://centauro_urdf/meshes/v2/collision/ankle-yaw.stl" scale="0.001 ${mirror*0.001} 0.001" />
        </geometry>
        </collision>
    </link>

    <joint name="j_wheel_${leg_num}" type="continuous">
        <parent link="ankle2_${leg_num}"/>
        <child link="wheel_${leg_num}"/>
        <origin xyz="${Wheel_Ox} ${mirror*Wheel_Oy} ${Wheel_Oz}" rpy="${Wheel_roll} ${Wheel_pitch} ${Wheel_yaw}"/>
        <axis xyz="0 0 ${mirror}"/>
       <limit  effort="${motor_C_effort}" velocity="${motor_C_velocity}"/>  <!-- 23 Nm, 1 rad/s-->
    </joint>

    <link name="wheel_${leg_num}">
        <inertial>
           <origin xyz="${Wheel_x} ${Wheel_y} ${mirror*Wheel_z}"/>
           <mass value="${Wheel_mass}"/>
           <inertia ixx="${Wheel_xx}" ixy="${Wheel_xy}" ixz="${mirror*Wheel_xz}" iyy="${Wheel_yy}" iyz="${mirror*Wheel_yz}" izz="${Wheel_zz}"/>
        </inertial>
  
        <visual>
           <origin xyz="0.0 0.0 0.0"  rpy="0.0 0.0 0.0"/>
           <geometry>
              <mesh filename="package://centauro_urdf/meshes/v2/wheel.stl" scale="0.001 0.001 ${mirror*0.001}" />
           </geometry>
           <material name="black"/>
        </visual>
        
        <collision>
           <origin xyz="0 0 0" rpy="0 0 0"/>
           <geometry>
              <cylinder length="0.11" radius="0.078"/>
           </geometry>
        </collision>
     </link> 

</xacro:macro>
<!-- /macro centauro_wheel -->

</robot>
